{"timestamp": "2025-10-17T22:06:42.894049Z", "level": "ERROR", "logger": "__main__", "message": "Mensagem de erro", "process_id": 13820, "thread_name": "MainThread", "filename": "test_logging_json.py", "line_number": 46, "function": "test_basic_logging"}
{"timestamp": "2025-10-17T22:06:42.905049Z", "level": "ERROR", "logger": "__main__", "message": "Erro ao executar operação matemática", "process_id": 13820, "thread_name": "MainThread", "filename": "logging_config.py", "line_number": 328, "function": "log_with_context", "operation": "division", "numerator": 10, "denominator": 0, "exc_info": true}
{"timestamp": "2025-10-17T22:06:42.907050Z", "level": "ERROR", "logger": "__main__", "message": "Exceção capturada", "process_id": 13820, "thread_name": "MainThread", "filename": "test_logging_json.py", "line_number": 127, "function": "test_exception_logging", "exception": {"type": "ZeroDivisionError", "message": "division by zero", "traceback": "Traceback (most recent call last):\n  File \"C:\\workstashion\\eda-aiminds-i2a2-rb\\tests\\utils\\test_logging_json.py\", line 116, in test_exception_logging\n    result = 10 / 0\n             ~~~^~~\nZeroDivisionError: division by zero"}}
{"timestamp": "2025-10-18T18:37:56.193444Z", "level": "ERROR", "logger": "src.data.data_processor", "message": "⚠️ VIOLAÇÃO DE CONFORMIDADE DETECTADA!\nAgente 'orchestrator_agent' tentou acessar CSV diretamente.\nApenas agentes autorizados podem ler CSV: ['ingestion_agent', 'data_loading_system', 'test_system']\nAgentes de resposta devem usar APENAS a tabela embeddings.", "process_id": 9620, "thread_name": "MainThread", "filename": "data_processor.py", "line_number": 112, "function": "_validate_csv_access_authorization"}
{"timestamp": "2025-10-18T18:42:26.634889Z", "level": "ERROR", "logger": "src.data.data_processor", "message": "⚠️ VIOLAÇÃO DE CONFORMIDADE DETECTADA!\nAgente 'orchestrator_agent' tentou acessar CSV diretamente.\nApenas agentes autorizados podem ler CSV: ['ingestion_agent', 'data_loading_system', 'test_system']\nAgentes de resposta devem usar APENAS a tabela embeddings.", "process_id": 14144, "thread_name": "MainThread", "filename": "data_processor.py", "line_number": 112, "function": "_validate_csv_access_authorization"}
{"timestamp": "2025-10-18T21:02:18.943118Z", "level": "ERROR", "logger": "agent.rag_data", "message": "Erro ao classificar intenção: 'NoneType' object has no attribute 'invoke'", "process_id": 10264, "thread_name": "MainThread", "filename": "intent_classifier.py", "line_number": 349, "function": "classify", "exception": {"type": "AttributeError", "message": "'NoneType' object has no attribute 'invoke'", "traceback": "Traceback (most recent call last):\n  File \"C:\\workstashion\\eda-aiminds-i2a2-rb\\src\\analysis\\intent_classifier.py\", line 310, in classify\n    response = self.llm.invoke(messages)\n               ^^^^^^^^^^^^^^^\nAttributeError: 'NoneType' object has no attribute 'invoke'"}}
{"timestamp": "2025-10-18T21:02:19.004114Z", "level": "ERROR", "logger": "src.agent.rag_data_agent_v4", "message": "❌ Erro na busca RAG: 'EmbeddingGenerator' object has no attribute 'generate'", "process_id": 10264, "thread_name": "MainThread", "filename": "rag_data_agent_v4.py", "line_number": 398, "function": "_search_rag_context"}
{"timestamp": "2025-10-18T21:02:21.102040Z", "level": "ERROR", "logger": "src.agent.rag_data_agent_v4", "message": "❌ Erro no query_v4: 'NoneType' object has no attribute 'invoke'", "process_id": 10264, "thread_name": "MainThread", "filename": "rag_data_agent_v4.py", "line_number": 341, "function": "query_v4", "exception": {"type": "AttributeError", "message": "'NoneType' object has no attribute 'invoke'", "traceback": "Traceback (most recent call last):\n  File \"C:\\workstashion\\eda-aiminds-i2a2-rb\\src\\agent\\rag_data_agent_v4.py\", line 282, in query_v4\n    response = self.llm.invoke(messages)\n               ^^^^^^^^^^^^^^^\nAttributeError: 'NoneType' object has no attribute 'invoke'"}}
{"timestamp": "2025-10-18T21:02:21.264031Z", "level": "ERROR", "logger": "agent.rag_data", "message": "Erro ao classificar intenção: 'NoneType' object has no attribute 'invoke'", "process_id": 10264, "thread_name": "MainThread", "filename": "intent_classifier.py", "line_number": 349, "function": "classify", "exception": {"type": "AttributeError", "message": "'NoneType' object has no attribute 'invoke'", "traceback": "Traceback (most recent call last):\n  File \"C:\\workstashion\\eda-aiminds-i2a2-rb\\src\\analysis\\intent_classifier.py\", line 310, in classify\n    response = self.llm.invoke(messages)\n               ^^^^^^^^^^^^^^^\nAttributeError: 'NoneType' object has no attribute 'invoke'"}}
{"timestamp": "2025-10-18T21:02:21.269031Z", "level": "ERROR", "logger": "src.agent.rag_data_agent_v4", "message": "❌ Erro na busca RAG: 'EmbeddingGenerator' object has no attribute 'generate'", "process_id": 10264, "thread_name": "MainThread", "filename": "rag_data_agent_v4.py", "line_number": 398, "function": "_search_rag_context"}
{"timestamp": "2025-10-18T21:02:21.988028Z", "level": "ERROR", "logger": "src.agent.rag_data_agent_v4", "message": "❌ Erro no query_v4: 'NoneType' object has no attribute 'invoke'", "process_id": 10264, "thread_name": "MainThread", "filename": "rag_data_agent_v4.py", "line_number": 341, "function": "query_v4", "exception": {"type": "AttributeError", "message": "'NoneType' object has no attribute 'invoke'", "traceback": "Traceback (most recent call last):\n  File \"C:\\workstashion\\eda-aiminds-i2a2-rb\\src\\agent\\rag_data_agent_v4.py\", line 282, in query_v4\n    response = self.llm.invoke(messages)\n               ^^^^^^^^^^^^^^^\nAttributeError: 'NoneType' object has no attribute 'invoke'"}}
{"timestamp": "2025-10-18T21:02:22.090580Z", "level": "ERROR", "logger": "agent.rag_data", "message": "Erro ao classificar intenção: 'NoneType' object has no attribute 'invoke'", "process_id": 10264, "thread_name": "MainThread", "filename": "intent_classifier.py", "line_number": 349, "function": "classify", "exception": {"type": "AttributeError", "message": "'NoneType' object has no attribute 'invoke'", "traceback": "Traceback (most recent call last):\n  File \"C:\\workstashion\\eda-aiminds-i2a2-rb\\src\\analysis\\intent_classifier.py\", line 310, in classify\n    response = self.llm.invoke(messages)\n               ^^^^^^^^^^^^^^^\nAttributeError: 'NoneType' object has no attribute 'invoke'"}}
{"timestamp": "2025-10-18T21:02:22.096580Z", "level": "ERROR", "logger": "src.agent.rag_data_agent_v4", "message": "❌ Erro na busca RAG: 'EmbeddingGenerator' object has no attribute 'generate'", "process_id": 10264, "thread_name": "MainThread", "filename": "rag_data_agent_v4.py", "line_number": 398, "function": "_search_rag_context"}
{"timestamp": "2025-10-18T21:02:22.732574Z", "level": "ERROR", "logger": "src.agent.rag_data_agent_v4", "message": "❌ Erro no query_v4: 'NoneType' object has no attribute 'invoke'", "process_id": 10264, "thread_name": "MainThread", "filename": "rag_data_agent_v4.py", "line_number": 341, "function": "query_v4", "exception": {"type": "AttributeError", "message": "'NoneType' object has no attribute 'invoke'", "traceback": "Traceback (most recent call last):\n  File \"C:\\workstashion\\eda-aiminds-i2a2-rb\\src\\agent\\rag_data_agent_v4.py\", line 282, in query_v4\n    response = self.llm.invoke(messages)\n               ^^^^^^^^^^^^^^^\nAttributeError: 'NoneType' object has no attribute 'invoke'"}}
{"timestamp": "2025-10-18T21:02:22.799574Z", "level": "ERROR", "logger": "agent.rag_data", "message": "Erro ao classificar intenção: 'NoneType' object has no attribute 'invoke'", "process_id": 10264, "thread_name": "MainThread", "filename": "intent_classifier.py", "line_number": 349, "function": "classify", "exception": {"type": "AttributeError", "message": "'NoneType' object has no attribute 'invoke'", "traceback": "Traceback (most recent call last):\n  File \"C:\\workstashion\\eda-aiminds-i2a2-rb\\src\\analysis\\intent_classifier.py\", line 310, in classify\n    response = self.llm.invoke(messages)\n               ^^^^^^^^^^^^^^^\nAttributeError: 'NoneType' object has no attribute 'invoke'"}}
{"timestamp": "2025-10-18T21:02:22.804569Z", "level": "ERROR", "logger": "src.agent.rag_data_agent_v4", "message": "❌ Erro na busca RAG: 'EmbeddingGenerator' object has no attribute 'generate'", "process_id": 10264, "thread_name": "MainThread", "filename": "rag_data_agent_v4.py", "line_number": 398, "function": "_search_rag_context"}
{"timestamp": "2025-10-18T21:02:23.443567Z", "level": "ERROR", "logger": "src.agent.rag_data_agent_v4", "message": "❌ Erro no query_v4: 'NoneType' object has no attribute 'invoke'", "process_id": 10264, "thread_name": "MainThread", "filename": "rag_data_agent_v4.py", "line_number": 341, "function": "query_v4", "exception": {"type": "AttributeError", "message": "'NoneType' object has no attribute 'invoke'", "traceback": "Traceback (most recent call last):\n  File \"C:\\workstashion\\eda-aiminds-i2a2-rb\\src\\agent\\rag_data_agent_v4.py\", line 282, in query_v4\n    response = self.llm.invoke(messages)\n               ^^^^^^^^^^^^^^^\nAttributeError: 'NoneType' object has no attribute 'invoke'"}}
{"timestamp": "2025-10-18T21:02:23.503563Z", "level": "ERROR", "logger": "agent.rag_data", "message": "Erro ao classificar intenção: 'NoneType' object has no attribute 'invoke'", "process_id": 10264, "thread_name": "MainThread", "filename": "intent_classifier.py", "line_number": 349, "function": "classify", "exception": {"type": "AttributeError", "message": "'NoneType' object has no attribute 'invoke'", "traceback": "Traceback (most recent call last):\n  File \"C:\\workstashion\\eda-aiminds-i2a2-rb\\src\\analysis\\intent_classifier.py\", line 310, in classify\n    response = self.llm.invoke(messages)\n               ^^^^^^^^^^^^^^^\nAttributeError: 'NoneType' object has no attribute 'invoke'"}}
{"timestamp": "2025-10-18T21:02:23.507561Z", "level": "ERROR", "logger": "src.agent.rag_data_agent_v4", "message": "❌ Erro na busca RAG: 'EmbeddingGenerator' object has no attribute 'generate'", "process_id": 10264, "thread_name": "MainThread", "filename": "rag_data_agent_v4.py", "line_number": 398, "function": "_search_rag_context"}
{"timestamp": "2025-10-18T21:02:24.128545Z", "level": "ERROR", "logger": "src.agent.rag_data_agent_v4", "message": "❌ Erro no query_v4: 'NoneType' object has no attribute 'invoke'", "process_id": 10264, "thread_name": "MainThread", "filename": "rag_data_agent_v4.py", "line_number": 341, "function": "query_v4", "exception": {"type": "AttributeError", "message": "'NoneType' object has no attribute 'invoke'", "traceback": "Traceback (most recent call last):\n  File \"C:\\workstashion\\eda-aiminds-i2a2-rb\\src\\agent\\rag_data_agent_v4.py\", line 282, in query_v4\n    response = self.llm.invoke(messages)\n               ^^^^^^^^^^^^^^^\nAttributeError: 'NoneType' object has no attribute 'invoke'"}}
{"timestamp": "2025-10-18T21:02:24.201542Z", "level": "ERROR", "logger": "agent.rag_data", "message": "Erro ao classificar intenção: 'NoneType' object has no attribute 'invoke'", "process_id": 10264, "thread_name": "MainThread", "filename": "intent_classifier.py", "line_number": 349, "function": "classify", "exception": {"type": "AttributeError", "message": "'NoneType' object has no attribute 'invoke'", "traceback": "Traceback (most recent call last):\n  File \"C:\\workstashion\\eda-aiminds-i2a2-rb\\src\\analysis\\intent_classifier.py\", line 310, in classify\n    response = self.llm.invoke(messages)\n               ^^^^^^^^^^^^^^^\nAttributeError: 'NoneType' object has no attribute 'invoke'"}}
{"timestamp": "2025-10-18T21:02:24.206544Z", "level": "ERROR", "logger": "src.agent.rag_data_agent_v4", "message": "❌ Erro na busca RAG: 'EmbeddingGenerator' object has no attribute 'generate'", "process_id": 10264, "thread_name": "MainThread", "filename": "rag_data_agent_v4.py", "line_number": 398, "function": "_search_rag_context"}
{"timestamp": "2025-10-18T21:02:24.838323Z", "level": "ERROR", "logger": "src.agent.rag_data_agent_v4", "message": "❌ Erro no query_v4: 'NoneType' object has no attribute 'invoke'", "process_id": 10264, "thread_name": "MainThread", "filename": "rag_data_agent_v4.py", "line_number": 341, "function": "query_v4", "exception": {"type": "AttributeError", "message": "'NoneType' object has no attribute 'invoke'", "traceback": "Traceback (most recent call last):\n  File \"C:\\workstashion\\eda-aiminds-i2a2-rb\\src\\agent\\rag_data_agent_v4.py\", line 282, in query_v4\n    response = self.llm.invoke(messages)\n               ^^^^^^^^^^^^^^^\nAttributeError: 'NoneType' object has no attribute 'invoke'"}}
{"timestamp": "2025-10-18T21:02:25.019321Z", "level": "ERROR", "logger": "agent.rag_data", "message": "Erro ao classificar intenção: 'NoneType' object has no attribute 'invoke'", "process_id": 10264, "thread_name": "MainThread", "filename": "intent_classifier.py", "line_number": 349, "function": "classify", "exception": {"type": "AttributeError", "message": "'NoneType' object has no attribute 'invoke'", "traceback": "Traceback (most recent call last):\n  File \"C:\\workstashion\\eda-aiminds-i2a2-rb\\src\\analysis\\intent_classifier.py\", line 310, in classify\n    response = self.llm.invoke(messages)\n               ^^^^^^^^^^^^^^^\nAttributeError: 'NoneType' object has no attribute 'invoke'"}}
{"timestamp": "2025-10-18T21:02:25.024321Z", "level": "ERROR", "logger": "src.agent.rag_data_agent_v4", "message": "❌ Erro na busca RAG: 'EmbeddingGenerator' object has no attribute 'generate'", "process_id": 10264, "thread_name": "MainThread", "filename": "rag_data_agent_v4.py", "line_number": 398, "function": "_search_rag_context"}
{"timestamp": "2025-10-18T21:02:25.679351Z", "level": "ERROR", "logger": "src.agent.rag_data_agent_v4", "message": "❌ Erro no query_v4: 'NoneType' object has no attribute 'invoke'", "process_id": 10264, "thread_name": "MainThread", "filename": "rag_data_agent_v4.py", "line_number": 341, "function": "query_v4", "exception": {"type": "AttributeError", "message": "'NoneType' object has no attribute 'invoke'", "traceback": "Traceback (most recent call last):\n  File \"C:\\workstashion\\eda-aiminds-i2a2-rb\\src\\agent\\rag_data_agent_v4.py\", line 282, in query_v4\n    response = self.llm.invoke(messages)\n               ^^^^^^^^^^^^^^^\nAttributeError: 'NoneType' object has no attribute 'invoke'"}}
{"timestamp": "2025-10-18T21:02:25.837306Z", "level": "ERROR", "logger": "agent.rag_data", "message": "Erro ao classificar intenção: 'NoneType' object has no attribute 'invoke'", "process_id": 10264, "thread_name": "MainThread", "filename": "intent_classifier.py", "line_number": 349, "function": "classify", "exception": {"type": "AttributeError", "message": "'NoneType' object has no attribute 'invoke'", "traceback": "Traceback (most recent call last):\n  File \"C:\\workstashion\\eda-aiminds-i2a2-rb\\src\\analysis\\intent_classifier.py\", line 310, in classify\n    response = self.llm.invoke(messages)\n               ^^^^^^^^^^^^^^^\nAttributeError: 'NoneType' object has no attribute 'invoke'"}}
{"timestamp": "2025-10-18T21:02:25.842304Z", "level": "ERROR", "logger": "src.agent.rag_data_agent_v4", "message": "❌ Erro na busca RAG: 'EmbeddingGenerator' object has no attribute 'generate'", "process_id": 10264, "thread_name": "MainThread", "filename": "rag_data_agent_v4.py", "line_number": 398, "function": "_search_rag_context"}
{"timestamp": "2025-10-18T21:02:26.473293Z", "level": "ERROR", "logger": "src.agent.rag_data_agent_v4", "message": "❌ Erro no query_v4: 'NoneType' object has no attribute 'invoke'", "process_id": 10264, "thread_name": "MainThread", "filename": "rag_data_agent_v4.py", "line_number": 341, "function": "query_v4", "exception": {"type": "AttributeError", "message": "'NoneType' object has no attribute 'invoke'", "traceback": "Traceback (most recent call last):\n  File \"C:\\workstashion\\eda-aiminds-i2a2-rb\\src\\agent\\rag_data_agent_v4.py\", line 282, in query_v4\n    response = self.llm.invoke(messages)\n               ^^^^^^^^^^^^^^^\nAttributeError: 'NoneType' object has no attribute 'invoke'"}}
{"timestamp": "2025-10-18T21:02:26.560292Z", "level": "ERROR", "logger": "agent.rag_data", "message": "Erro ao classificar intenção: 'NoneType' object has no attribute 'invoke'", "process_id": 10264, "thread_name": "MainThread", "filename": "intent_classifier.py", "line_number": 349, "function": "classify", "exception": {"type": "AttributeError", "message": "'NoneType' object has no attribute 'invoke'", "traceback": "Traceback (most recent call last):\n  File \"C:\\workstashion\\eda-aiminds-i2a2-rb\\src\\analysis\\intent_classifier.py\", line 310, in classify\n    response = self.llm.invoke(messages)\n               ^^^^^^^^^^^^^^^\nAttributeError: 'NoneType' object has no attribute 'invoke'"}}
{"timestamp": "2025-10-18T21:02:26.563293Z", "level": "ERROR", "logger": "src.agent.rag_data_agent_v4", "message": "❌ Erro na busca RAG: 'EmbeddingGenerator' object has no attribute 'generate'", "process_id": 10264, "thread_name": "MainThread", "filename": "rag_data_agent_v4.py", "line_number": 398, "function": "_search_rag_context"}
{"timestamp": "2025-10-18T21:02:27.241564Z", "level": "ERROR", "logger": "src.agent.rag_data_agent_v4", "message": "❌ Erro no query_v4: 'NoneType' object has no attribute 'invoke'", "process_id": 10264, "thread_name": "MainThread", "filename": "rag_data_agent_v4.py", "line_number": 341, "function": "query_v4", "exception": {"type": "AttributeError", "message": "'NoneType' object has no attribute 'invoke'", "traceback": "Traceback (most recent call last):\n  File \"C:\\workstashion\\eda-aiminds-i2a2-rb\\src\\agent\\rag_data_agent_v4.py\", line 282, in query_v4\n    response = self.llm.invoke(messages)\n               ^^^^^^^^^^^^^^^\nAttributeError: 'NoneType' object has no attribute 'invoke'"}}
{"timestamp": "2025-10-18T21:02:27.387564Z", "level": "ERROR", "logger": "agent.rag_data", "message": "Erro ao classificar intenção: 'NoneType' object has no attribute 'invoke'", "process_id": 10264, "thread_name": "MainThread", "filename": "intent_classifier.py", "line_number": 349, "function": "classify", "exception": {"type": "AttributeError", "message": "'NoneType' object has no attribute 'invoke'", "traceback": "Traceback (most recent call last):\n  File \"C:\\workstashion\\eda-aiminds-i2a2-rb\\src\\analysis\\intent_classifier.py\", line 310, in classify\n    response = self.llm.invoke(messages)\n               ^^^^^^^^^^^^^^^\nAttributeError: 'NoneType' object has no attribute 'invoke'"}}
{"timestamp": "2025-10-18T21:02:27.392802Z", "level": "ERROR", "logger": "src.agent.rag_data_agent_v4", "message": "❌ Erro na busca RAG: 'EmbeddingGenerator' object has no attribute 'generate'", "process_id": 10264, "thread_name": "MainThread", "filename": "rag_data_agent_v4.py", "line_number": 398, "function": "_search_rag_context"}
{"timestamp": "2025-10-18T21:02:27.639562Z", "level": "ERROR", "logger": "src.agent.rag_data_agent_v4", "message": "❌ Erro no query_v4: 'NoneType' object has no attribute 'invoke'", "process_id": 10264, "thread_name": "MainThread", "filename": "rag_data_agent_v4.py", "line_number": 341, "function": "query_v4", "exception": {"type": "AttributeError", "message": "'NoneType' object has no attribute 'invoke'", "traceback": "Traceback (most recent call last):\n  File \"C:\\workstashion\\eda-aiminds-i2a2-rb\\src\\agent\\rag_data_agent_v4.py\", line 282, in query_v4\n    response = self.llm.invoke(messages)\n               ^^^^^^^^^^^^^^^\nAttributeError: 'NoneType' object has no attribute 'invoke'"}}
{"timestamp": "2025-10-18T21:02:28.418545Z", "level": "ERROR", "logger": "agent.rag_data", "message": "Erro ao classificar intenção: 'NoneType' object has no attribute 'invoke'", "process_id": 10264, "thread_name": "MainThread", "filename": "intent_classifier.py", "line_number": 349, "function": "classify", "exception": {"type": "AttributeError", "message": "'NoneType' object has no attribute 'invoke'", "traceback": "Traceback (most recent call last):\n  File \"C:\\workstashion\\eda-aiminds-i2a2-rb\\src\\analysis\\intent_classifier.py\", line 310, in classify\n    response = self.llm.invoke(messages)\n               ^^^^^^^^^^^^^^^\nAttributeError: 'NoneType' object has no attribute 'invoke'"}}
{"timestamp": "2025-10-18T21:02:28.424545Z", "level": "ERROR", "logger": "src.agent.rag_data_agent_v4", "message": "❌ Erro na busca RAG: 'EmbeddingGenerator' object has no attribute 'generate'", "process_id": 10264, "thread_name": "MainThread", "filename": "rag_data_agent_v4.py", "line_number": 398, "function": "_search_rag_context"}
{"timestamp": "2025-10-18T21:02:29.027687Z", "level": "ERROR", "logger": "src.agent.rag_data_agent_v4", "message": "❌ Erro no query_v4: 'NoneType' object has no attribute 'invoke'", "process_id": 10264, "thread_name": "MainThread", "filename": "rag_data_agent_v4.py", "line_number": 341, "function": "query_v4", "exception": {"type": "AttributeError", "message": "'NoneType' object has no attribute 'invoke'", "traceback": "Traceback (most recent call last):\n  File \"C:\\workstashion\\eda-aiminds-i2a2-rb\\src\\agent\\rag_data_agent_v4.py\", line 282, in query_v4\n    response = self.llm.invoke(messages)\n               ^^^^^^^^^^^^^^^\nAttributeError: 'NoneType' object has no attribute 'invoke'"}}
{"timestamp": "2025-10-18T21:02:29.147535Z", "level": "ERROR", "logger": "agent.rag_data", "message": "Erro ao classificar intenção: 'NoneType' object has no attribute 'invoke'", "process_id": 10264, "thread_name": "MainThread", "filename": "intent_classifier.py", "line_number": 349, "function": "classify", "exception": {"type": "AttributeError", "message": "'NoneType' object has no attribute 'invoke'", "traceback": "Traceback (most recent call last):\n  File \"C:\\workstashion\\eda-aiminds-i2a2-rb\\src\\analysis\\intent_classifier.py\", line 310, in classify\n    response = self.llm.invoke(messages)\n               ^^^^^^^^^^^^^^^\nAttributeError: 'NoneType' object has no attribute 'invoke'"}}
{"timestamp": "2025-10-18T21:02:29.152536Z", "level": "ERROR", "logger": "src.agent.rag_data_agent_v4", "message": "❌ Erro na busca RAG: 'EmbeddingGenerator' object has no attribute 'generate'", "process_id": 10264, "thread_name": "MainThread", "filename": "rag_data_agent_v4.py", "line_number": 398, "function": "_search_rag_context"}
{"timestamp": "2025-10-18T21:02:29.725832Z", "level": "ERROR", "logger": "src.agent.rag_data_agent_v4", "message": "❌ Erro no query_v4: 'NoneType' object has no attribute 'invoke'", "process_id": 10264, "thread_name": "MainThread", "filename": "rag_data_agent_v4.py", "line_number": 341, "function": "query_v4", "exception": {"type": "AttributeError", "message": "'NoneType' object has no attribute 'invoke'", "traceback": "Traceback (most recent call last):\n  File \"C:\\workstashion\\eda-aiminds-i2a2-rb\\src\\agent\\rag_data_agent_v4.py\", line 282, in query_v4\n    response = self.llm.invoke(messages)\n               ^^^^^^^^^^^^^^^\nAttributeError: 'NoneType' object has no attribute 'invoke'"}}
{"timestamp": "2025-10-18T21:02:29.799710Z", "level": "ERROR", "logger": "agent.rag_data", "message": "Erro ao classificar intenção: 'NoneType' object has no attribute 'invoke'", "process_id": 10264, "thread_name": "MainThread", "filename": "intent_classifier.py", "line_number": 349, "function": "classify", "exception": {"type": "AttributeError", "message": "'NoneType' object has no attribute 'invoke'", "traceback": "Traceback (most recent call last):\n  File \"C:\\workstashion\\eda-aiminds-i2a2-rb\\src\\analysis\\intent_classifier.py\", line 310, in classify\n    response = self.llm.invoke(messages)\n               ^^^^^^^^^^^^^^^\nAttributeError: 'NoneType' object has no attribute 'invoke'"}}
{"timestamp": "2025-10-18T21:02:29.803712Z", "level": "ERROR", "logger": "src.agent.rag_data_agent_v4", "message": "❌ Erro na busca RAG: 'EmbeddingGenerator' object has no attribute 'generate'", "process_id": 10264, "thread_name": "MainThread", "filename": "rag_data_agent_v4.py", "line_number": 398, "function": "_search_rag_context"}
{"timestamp": "2025-10-18T21:02:30.020857Z", "level": "ERROR", "logger": "src.agent.rag_data_agent_v4", "message": "❌ Erro no query_v4: 'NoneType' object has no attribute 'invoke'", "process_id": 10264, "thread_name": "MainThread", "filename": "rag_data_agent_v4.py", "line_number": 341, "function": "query_v4", "exception": {"type": "AttributeError", "message": "'NoneType' object has no attribute 'invoke'", "traceback": "Traceback (most recent call last):\n  File \"C:\\workstashion\\eda-aiminds-i2a2-rb\\src\\agent\\rag_data_agent_v4.py\", line 282, in query_v4\n    response = self.llm.invoke(messages)\n               ^^^^^^^^^^^^^^^\nAttributeError: 'NoneType' object has no attribute 'invoke'"}}
{"timestamp": "2025-10-18T21:02:30.100855Z", "level": "ERROR", "logger": "agent.rag_data", "message": "Erro ao classificar intenção: 'NoneType' object has no attribute 'invoke'", "process_id": 10264, "thread_name": "MainThread", "filename": "intent_classifier.py", "line_number": 349, "function": "classify", "exception": {"type": "AttributeError", "message": "'NoneType' object has no attribute 'invoke'", "traceback": "Traceback (most recent call last):\n  File \"C:\\workstashion\\eda-aiminds-i2a2-rb\\src\\analysis\\intent_classifier.py\", line 310, in classify\n    response = self.llm.invoke(messages)\n               ^^^^^^^^^^^^^^^\nAttributeError: 'NoneType' object has no attribute 'invoke'"}}
{"timestamp": "2025-10-18T21:02:30.104856Z", "level": "ERROR", "logger": "src.agent.rag_data_agent_v4", "message": "❌ Erro na busca RAG: 'EmbeddingGenerator' object has no attribute 'generate'", "process_id": 10264, "thread_name": "MainThread", "filename": "rag_data_agent_v4.py", "line_number": 398, "function": "_search_rag_context"}
{"timestamp": "2025-10-18T21:02:30.332855Z", "level": "ERROR", "logger": "src.agent.rag_data_agent_v4", "message": "❌ Erro no query_v4: 'NoneType' object has no attribute 'invoke'", "process_id": 10264, "thread_name": "MainThread", "filename": "rag_data_agent_v4.py", "line_number": 341, "function": "query_v4", "exception": {"type": "AttributeError", "message": "'NoneType' object has no attribute 'invoke'", "traceback": "Traceback (most recent call last):\n  File \"C:\\workstashion\\eda-aiminds-i2a2-rb\\src\\agent\\rag_data_agent_v4.py\", line 282, in query_v4\n    response = self.llm.invoke(messages)\n               ^^^^^^^^^^^^^^^\nAttributeError: 'NoneType' object has no attribute 'invoke'"}}
{"timestamp": "2025-10-18T21:02:30.404859Z", "level": "ERROR", "logger": "agent.rag_data", "message": "Erro ao classificar intenção: 'NoneType' object has no attribute 'invoke'", "process_id": 10264, "thread_name": "MainThread", "filename": "intent_classifier.py", "line_number": 349, "function": "classify", "exception": {"type": "AttributeError", "message": "'NoneType' object has no attribute 'invoke'", "traceback": "Traceback (most recent call last):\n  File \"C:\\workstashion\\eda-aiminds-i2a2-rb\\src\\analysis\\intent_classifier.py\", line 310, in classify\n    response = self.llm.invoke(messages)\n               ^^^^^^^^^^^^^^^\nAttributeError: 'NoneType' object has no attribute 'invoke'"}}
{"timestamp": "2025-10-18T21:02:30.408874Z", "level": "ERROR", "logger": "src.agent.rag_data_agent_v4", "message": "❌ Erro na busca RAG: 'EmbeddingGenerator' object has no attribute 'generate'", "process_id": 10264, "thread_name": "MainThread", "filename": "rag_data_agent_v4.py", "line_number": 398, "function": "_search_rag_context"}
{"timestamp": "2025-10-18T21:02:30.990843Z", "level": "ERROR", "logger": "src.agent.rag_data_agent_v4", "message": "❌ Erro no query_v4: 'NoneType' object has no attribute 'invoke'", "process_id": 10264, "thread_name": "MainThread", "filename": "rag_data_agent_v4.py", "line_number": 341, "function": "query_v4", "exception": {"type": "AttributeError", "message": "'NoneType' object has no attribute 'invoke'", "traceback": "Traceback (most recent call last):\n  File \"C:\\workstashion\\eda-aiminds-i2a2-rb\\src\\agent\\rag_data_agent_v4.py\", line 282, in query_v4\n    response = self.llm.invoke(messages)\n               ^^^^^^^^^^^^^^^\nAttributeError: 'NoneType' object has no attribute 'invoke'"}}
{"timestamp": "2025-10-18T21:02:31.071889Z", "level": "ERROR", "logger": "agent.rag_data", "message": "Erro ao classificar intenção: 'NoneType' object has no attribute 'invoke'", "process_id": 10264, "thread_name": "MainThread", "filename": "intent_classifier.py", "line_number": 349, "function": "classify", "exception": {"type": "AttributeError", "message": "'NoneType' object has no attribute 'invoke'", "traceback": "Traceback (most recent call last):\n  File \"C:\\workstashion\\eda-aiminds-i2a2-rb\\src\\analysis\\intent_classifier.py\", line 310, in classify\n    response = self.llm.invoke(messages)\n               ^^^^^^^^^^^^^^^\nAttributeError: 'NoneType' object has no attribute 'invoke'"}}
{"timestamp": "2025-10-18T21:02:31.076905Z", "level": "ERROR", "logger": "src.agent.rag_data_agent_v4", "message": "❌ Erro na busca RAG: 'EmbeddingGenerator' object has no attribute 'generate'", "process_id": 10264, "thread_name": "MainThread", "filename": "rag_data_agent_v4.py", "line_number": 398, "function": "_search_rag_context"}
{"timestamp": "2025-10-18T21:02:31.666834Z", "level": "ERROR", "logger": "src.agent.rag_data_agent_v4", "message": "❌ Erro no query_v4: 'NoneType' object has no attribute 'invoke'", "process_id": 10264, "thread_name": "MainThread", "filename": "rag_data_agent_v4.py", "line_number": 341, "function": "query_v4", "exception": {"type": "AttributeError", "message": "'NoneType' object has no attribute 'invoke'", "traceback": "Traceback (most recent call last):\n  File \"C:\\workstashion\\eda-aiminds-i2a2-rb\\src\\agent\\rag_data_agent_v4.py\", line 282, in query_v4\n    response = self.llm.invoke(messages)\n               ^^^^^^^^^^^^^^^\nAttributeError: 'NoneType' object has no attribute 'invoke'"}}
{"timestamp": "2025-10-18T21:02:31.733830Z", "level": "ERROR", "logger": "agent.rag_data", "message": "Erro ao classificar intenção: 'NoneType' object has no attribute 'invoke'", "process_id": 10264, "thread_name": "MainThread", "filename": "intent_classifier.py", "line_number": 349, "function": "classify", "exception": {"type": "AttributeError", "message": "'NoneType' object has no attribute 'invoke'", "traceback": "Traceback (most recent call last):\n  File \"C:\\workstashion\\eda-aiminds-i2a2-rb\\src\\analysis\\intent_classifier.py\", line 310, in classify\n    response = self.llm.invoke(messages)\n               ^^^^^^^^^^^^^^^\nAttributeError: 'NoneType' object has no attribute 'invoke'"}}
{"timestamp": "2025-10-18T21:02:31.738830Z", "level": "ERROR", "logger": "src.agent.rag_data_agent_v4", "message": "❌ Erro na busca RAG: 'EmbeddingGenerator' object has no attribute 'generate'", "process_id": 10264, "thread_name": "MainThread", "filename": "rag_data_agent_v4.py", "line_number": 398, "function": "_search_rag_context"}
{"timestamp": "2025-10-18T21:02:31.956537Z", "level": "ERROR", "logger": "src.agent.rag_data_agent_v4", "message": "❌ Erro no query_v4: 'NoneType' object has no attribute 'invoke'", "process_id": 10264, "thread_name": "MainThread", "filename": "rag_data_agent_v4.py", "line_number": 341, "function": "query_v4", "exception": {"type": "AttributeError", "message": "'NoneType' object has no attribute 'invoke'", "traceback": "Traceback (most recent call last):\n  File \"C:\\workstashion\\eda-aiminds-i2a2-rb\\src\\agent\\rag_data_agent_v4.py\", line 282, in query_v4\n    response = self.llm.invoke(messages)\n               ^^^^^^^^^^^^^^^\nAttributeError: 'NoneType' object has no attribute 'invoke'"}}
{"timestamp": "2025-10-18T21:09:51.586806Z", "level": "ERROR", "logger": "agent.rag_data", "message": "Erro ao classificar intenção: 'NoneType' object has no attribute 'invoke'", "process_id": 8656, "thread_name": "MainThread", "filename": "intent_classifier.py", "line_number": 349, "function": "classify", "exception": {"type": "AttributeError", "message": "'NoneType' object has no attribute 'invoke'", "traceback": "Traceback (most recent call last):\n  File \"C:\\workstashion\\eda-aiminds-i2a2-rb\\src\\analysis\\intent_classifier.py\", line 310, in classify\n    response = self.llm.invoke(messages)\n               ^^^^^^^^^^^^^^^\nAttributeError: 'NoneType' object has no attribute 'invoke'"}}
{"timestamp": "2025-10-18T21:09:54.381946Z", "level": "ERROR", "logger": "src.agent.rag_data_agent_v4", "message": "❌ Erro na busca RAG: {'message': 'Could not find the function public.match_embeddings_v2(match_count, match_threshold, query_embedding) in the schema cache', 'code': 'PGRST202', 'hint': 'Perhaps you meant to call the function public.match_embeddings', 'details': 'Searched for the function public.match_embeddings_v2 with parameters match_count, match_threshold, query_embedding or with a single unnamed json/jsonb parameter, but no matches were found in the schema cache.'}", "process_id": 8656, "thread_name": "MainThread", "filename": "rag_data_agent_v4.py", "line_number": 399, "function": "_search_rag_context"}
{"timestamp": "2025-10-18T21:09:54.952929Z", "level": "ERROR", "logger": "src.agent.rag_data_agent_v4", "message": "❌ Erro no query_v4: 'NoneType' object has no attribute 'invoke'", "process_id": 8656, "thread_name": "MainThread", "filename": "rag_data_agent_v4.py", "line_number": 341, "function": "query_v4", "exception": {"type": "AttributeError", "message": "'NoneType' object has no attribute 'invoke'", "traceback": "Traceback (most recent call last):\n  File \"C:\\workstashion\\eda-aiminds-i2a2-rb\\src\\agent\\rag_data_agent_v4.py\", line 282, in query_v4\n    response = self.llm.invoke(messages)\n               ^^^^^^^^^^^^^^^\nAttributeError: 'NoneType' object has no attribute 'invoke'"}}
{"timestamp": "2025-10-18T21:09:55.135928Z", "level": "ERROR", "logger": "agent.rag_data", "message": "Erro ao classificar intenção: 'NoneType' object has no attribute 'invoke'", "process_id": 8656, "thread_name": "MainThread", "filename": "intent_classifier.py", "line_number": 349, "function": "classify", "exception": {"type": "AttributeError", "message": "'NoneType' object has no attribute 'invoke'", "traceback": "Traceback (most recent call last):\n  File \"C:\\workstashion\\eda-aiminds-i2a2-rb\\src\\analysis\\intent_classifier.py\", line 310, in classify\n    response = self.llm.invoke(messages)\n               ^^^^^^^^^^^^^^^\nAttributeError: 'NoneType' object has no attribute 'invoke'"}}
{"timestamp": "2025-10-18T21:09:56.808737Z", "level": "ERROR", "logger": "src.agent.rag_data_agent_v4", "message": "❌ Erro na busca RAG: {'message': 'Could not find the function public.match_embeddings_v2(match_count, match_threshold, query_embedding) in the schema cache', 'code': 'PGRST202', 'hint': 'Perhaps you meant to call the function public.match_embeddings', 'details': 'Searched for the function public.match_embeddings_v2 with parameters match_count, match_threshold, query_embedding or with a single unnamed json/jsonb parameter, but no matches were found in the schema cache.'}", "process_id": 8656, "thread_name": "MainThread", "filename": "rag_data_agent_v4.py", "line_number": 399, "function": "_search_rag_context"}
{"timestamp": "2025-10-18T21:09:57.079731Z", "level": "ERROR", "logger": "src.agent.rag_data_agent_v4", "message": "❌ Erro no query_v4: 'NoneType' object has no attribute 'invoke'", "process_id": 8656, "thread_name": "MainThread", "filename": "rag_data_agent_v4.py", "line_number": 341, "function": "query_v4", "exception": {"type": "AttributeError", "message": "'NoneType' object has no attribute 'invoke'", "traceback": "Traceback (most recent call last):\n  File \"C:\\workstashion\\eda-aiminds-i2a2-rb\\src\\agent\\rag_data_agent_v4.py\", line 282, in query_v4\n    response = self.llm.invoke(messages)\n               ^^^^^^^^^^^^^^^\nAttributeError: 'NoneType' object has no attribute 'invoke'"}}
{"timestamp": "2025-10-18T21:09:57.243737Z", "level": "ERROR", "logger": "agent.rag_data", "message": "Erro ao classificar intenção: 'NoneType' object has no attribute 'invoke'", "process_id": 8656, "thread_name": "MainThread", "filename": "intent_classifier.py", "line_number": 349, "function": "classify", "exception": {"type": "AttributeError", "message": "'NoneType' object has no attribute 'invoke'", "traceback": "Traceback (most recent call last):\n  File \"C:\\workstashion\\eda-aiminds-i2a2-rb\\src\\analysis\\intent_classifier.py\", line 310, in classify\n    response = self.llm.invoke(messages)\n               ^^^^^^^^^^^^^^^\nAttributeError: 'NoneType' object has no attribute 'invoke'"}}
{"timestamp": "2025-10-18T21:09:58.678593Z", "level": "ERROR", "logger": "src.agent.rag_data_agent_v4", "message": "❌ Erro na busca RAG: {'message': 'Could not find the function public.match_embeddings_v2(match_count, match_threshold, query_embedding) in the schema cache', 'code': 'PGRST202', 'hint': 'Perhaps you meant to call the function public.match_embeddings', 'details': 'Searched for the function public.match_embeddings_v2 with parameters match_count, match_threshold, query_embedding or with a single unnamed json/jsonb parameter, but no matches were found in the schema cache.'}", "process_id": 8656, "thread_name": "MainThread", "filename": "rag_data_agent_v4.py", "line_number": 399, "function": "_search_rag_context"}
{"timestamp": "2025-10-18T21:09:58.941129Z", "level": "ERROR", "logger": "src.agent.rag_data_agent_v4", "message": "❌ Erro no query_v4: 'NoneType' object has no attribute 'invoke'", "process_id": 8656, "thread_name": "MainThread", "filename": "rag_data_agent_v4.py", "line_number": 341, "function": "query_v4", "exception": {"type": "AttributeError", "message": "'NoneType' object has no attribute 'invoke'", "traceback": "Traceback (most recent call last):\n  File \"C:\\workstashion\\eda-aiminds-i2a2-rb\\src\\agent\\rag_data_agent_v4.py\", line 282, in query_v4\n    response = self.llm.invoke(messages)\n               ^^^^^^^^^^^^^^^\nAttributeError: 'NoneType' object has no attribute 'invoke'"}}
{"timestamp": "2025-10-18T21:09:59.091124Z", "level": "ERROR", "logger": "agent.rag_data", "message": "Erro ao classificar intenção: 'NoneType' object has no attribute 'invoke'", "process_id": 8656, "thread_name": "MainThread", "filename": "intent_classifier.py", "line_number": 349, "function": "classify", "exception": {"type": "AttributeError", "message": "'NoneType' object has no attribute 'invoke'", "traceback": "Traceback (most recent call last):\n  File \"C:\\workstashion\\eda-aiminds-i2a2-rb\\src\\analysis\\intent_classifier.py\", line 310, in classify\n    response = self.llm.invoke(messages)\n               ^^^^^^^^^^^^^^^\nAttributeError: 'NoneType' object has no attribute 'invoke'"}}
{"timestamp": "2025-10-18T21:10:00.651143Z", "level": "ERROR", "logger": "src.agent.rag_data_agent_v4", "message": "❌ Erro na busca RAG: {'message': 'Could not find the function public.match_embeddings_v2(match_count, match_threshold, query_embedding) in the schema cache', 'code': 'PGRST202', 'hint': 'Perhaps you meant to call the function public.match_embeddings', 'details': 'Searched for the function public.match_embeddings_v2 with parameters match_count, match_threshold, query_embedding or with a single unnamed json/jsonb parameter, but no matches were found in the schema cache.'}", "process_id": 8656, "thread_name": "MainThread", "filename": "rag_data_agent_v4.py", "line_number": 399, "function": "_search_rag_context"}
{"timestamp": "2025-10-18T21:10:00.870142Z", "level": "ERROR", "logger": "src.agent.rag_data_agent_v4", "message": "❌ Erro no query_v4: 'NoneType' object has no attribute 'invoke'", "process_id": 8656, "thread_name": "MainThread", "filename": "rag_data_agent_v4.py", "line_number": 341, "function": "query_v4", "exception": {"type": "AttributeError", "message": "'NoneType' object has no attribute 'invoke'", "traceback": "Traceback (most recent call last):\n  File \"C:\\workstashion\\eda-aiminds-i2a2-rb\\src\\agent\\rag_data_agent_v4.py\", line 282, in query_v4\n    response = self.llm.invoke(messages)\n               ^^^^^^^^^^^^^^^\nAttributeError: 'NoneType' object has no attribute 'invoke'"}}
{"timestamp": "2025-10-18T21:10:01.137137Z", "level": "ERROR", "logger": "agent.rag_data", "message": "Erro ao classificar intenção: 'NoneType' object has no attribute 'invoke'", "process_id": 8656, "thread_name": "MainThread", "filename": "intent_classifier.py", "line_number": 349, "function": "classify", "exception": {"type": "AttributeError", "message": "'NoneType' object has no attribute 'invoke'", "traceback": "Traceback (most recent call last):\n  File \"C:\\workstashion\\eda-aiminds-i2a2-rb\\src\\analysis\\intent_classifier.py\", line 310, in classify\n    response = self.llm.invoke(messages)\n               ^^^^^^^^^^^^^^^\nAttributeError: 'NoneType' object has no attribute 'invoke'"}}
{"timestamp": "2025-10-18T21:10:02.458488Z", "level": "ERROR", "logger": "src.agent.rag_data_agent_v4", "message": "❌ Erro na busca RAG: {'message': 'Could not find the function public.match_embeddings_v2(match_count, match_threshold, query_embedding) in the schema cache', 'code': 'PGRST202', 'hint': 'Perhaps you meant to call the function public.match_embeddings', 'details': 'Searched for the function public.match_embeddings_v2 with parameters match_count, match_threshold, query_embedding or with a single unnamed json/jsonb parameter, but no matches were found in the schema cache.'}", "process_id": 8656, "thread_name": "MainThread", "filename": "rag_data_agent_v4.py", "line_number": 399, "function": "_search_rag_context"}
{"timestamp": "2025-10-18T21:10:02.718483Z", "level": "ERROR", "logger": "src.agent.rag_data_agent_v4", "message": "❌ Erro no query_v4: 'NoneType' object has no attribute 'invoke'", "process_id": 8656, "thread_name": "MainThread", "filename": "rag_data_agent_v4.py", "line_number": 341, "function": "query_v4", "exception": {"type": "AttributeError", "message": "'NoneType' object has no attribute 'invoke'", "traceback": "Traceback (most recent call last):\n  File \"C:\\workstashion\\eda-aiminds-i2a2-rb\\src\\agent\\rag_data_agent_v4.py\", line 282, in query_v4\n    response = self.llm.invoke(messages)\n               ^^^^^^^^^^^^^^^\nAttributeError: 'NoneType' object has no attribute 'invoke'"}}
{"timestamp": "2025-10-18T21:10:02.955479Z", "level": "ERROR", "logger": "agent.rag_data", "message": "Erro ao classificar intenção: 'NoneType' object has no attribute 'invoke'", "process_id": 8656, "thread_name": "MainThread", "filename": "intent_classifier.py", "line_number": 349, "function": "classify", "exception": {"type": "AttributeError", "message": "'NoneType' object has no attribute 'invoke'", "traceback": "Traceback (most recent call last):\n  File \"C:\\workstashion\\eda-aiminds-i2a2-rb\\src\\analysis\\intent_classifier.py\", line 310, in classify\n    response = self.llm.invoke(messages)\n               ^^^^^^^^^^^^^^^\nAttributeError: 'NoneType' object has no attribute 'invoke'"}}
{"timestamp": "2025-10-18T21:10:04.261003Z", "level": "ERROR", "logger": "src.agent.rag_data_agent_v4", "message": "❌ Erro na busca RAG: {'message': 'Could not find the function public.match_embeddings_v2(match_count, match_threshold, query_embedding) in the schema cache', 'code': 'PGRST202', 'hint': 'Perhaps you meant to call the function public.match_embeddings', 'details': 'Searched for the function public.match_embeddings_v2 with parameters match_count, match_threshold, query_embedding or with a single unnamed json/jsonb parameter, but no matches were found in the schema cache.'}", "process_id": 8656, "thread_name": "MainThread", "filename": "rag_data_agent_v4.py", "line_number": 399, "function": "_search_rag_context"}
{"timestamp": "2025-10-18T21:10:04.472997Z", "level": "ERROR", "logger": "src.agent.rag_data_agent_v4", "message": "❌ Erro no query_v4: 'NoneType' object has no attribute 'invoke'", "process_id": 8656, "thread_name": "MainThread", "filename": "rag_data_agent_v4.py", "line_number": 341, "function": "query_v4", "exception": {"type": "AttributeError", "message": "'NoneType' object has no attribute 'invoke'", "traceback": "Traceback (most recent call last):\n  File \"C:\\workstashion\\eda-aiminds-i2a2-rb\\src\\agent\\rag_data_agent_v4.py\", line 282, in query_v4\n    response = self.llm.invoke(messages)\n               ^^^^^^^^^^^^^^^\nAttributeError: 'NoneType' object has no attribute 'invoke'"}}
{"timestamp": "2025-10-18T21:10:04.704566Z", "level": "ERROR", "logger": "agent.rag_data", "message": "Erro ao classificar intenção: 'NoneType' object has no attribute 'invoke'", "process_id": 8656, "thread_name": "MainThread", "filename": "intent_classifier.py", "line_number": 349, "function": "classify", "exception": {"type": "AttributeError", "message": "'NoneType' object has no attribute 'invoke'", "traceback": "Traceback (most recent call last):\n  File \"C:\\workstashion\\eda-aiminds-i2a2-rb\\src\\analysis\\intent_classifier.py\", line 310, in classify\n    response = self.llm.invoke(messages)\n               ^^^^^^^^^^^^^^^\nAttributeError: 'NoneType' object has no attribute 'invoke'"}}
{"timestamp": "2025-10-18T21:10:06.153085Z", "level": "ERROR", "logger": "src.agent.rag_data_agent_v4", "message": "❌ Erro na busca RAG: {'message': 'Could not find the function public.match_embeddings_v2(match_count, match_threshold, query_embedding) in the schema cache', 'code': 'PGRST202', 'hint': 'Perhaps you meant to call the function public.match_embeddings', 'details': 'Searched for the function public.match_embeddings_v2 with parameters match_count, match_threshold, query_embedding or with a single unnamed json/jsonb parameter, but no matches were found in the schema cache.'}", "process_id": 8656, "thread_name": "MainThread", "filename": "rag_data_agent_v4.py", "line_number": 399, "function": "_search_rag_context"}
{"timestamp": "2025-10-18T21:10:06.370078Z", "level": "ERROR", "logger": "src.agent.rag_data_agent_v4", "message": "❌ Erro no query_v4: 'NoneType' object has no attribute 'invoke'", "process_id": 8656, "thread_name": "MainThread", "filename": "rag_data_agent_v4.py", "line_number": 341, "function": "query_v4", "exception": {"type": "AttributeError", "message": "'NoneType' object has no attribute 'invoke'", "traceback": "Traceback (most recent call last):\n  File \"C:\\workstashion\\eda-aiminds-i2a2-rb\\src\\agent\\rag_data_agent_v4.py\", line 282, in query_v4\n    response = self.llm.invoke(messages)\n               ^^^^^^^^^^^^^^^\nAttributeError: 'NoneType' object has no attribute 'invoke'"}}
{"timestamp": "2025-10-18T21:10:06.466078Z", "level": "ERROR", "logger": "agent.rag_data", "message": "Erro ao classificar intenção: 'NoneType' object has no attribute 'invoke'", "process_id": 8656, "thread_name": "MainThread", "filename": "intent_classifier.py", "line_number": 349, "function": "classify", "exception": {"type": "AttributeError", "message": "'NoneType' object has no attribute 'invoke'", "traceback": "Traceback (most recent call last):\n  File \"C:\\workstashion\\eda-aiminds-i2a2-rb\\src\\analysis\\intent_classifier.py\", line 310, in classify\n    response = self.llm.invoke(messages)\n               ^^^^^^^^^^^^^^^\nAttributeError: 'NoneType' object has no attribute 'invoke'"}}
{"timestamp": "2025-10-18T21:10:07.924743Z", "level": "ERROR", "logger": "src.agent.rag_data_agent_v4", "message": "❌ Erro na busca RAG: {'message': 'Could not find the function public.match_embeddings_v2(match_count, match_threshold, query_embedding) in the schema cache', 'code': 'PGRST202', 'hint': 'Perhaps you meant to call the function public.match_embeddings', 'details': 'Searched for the function public.match_embeddings_v2 with parameters match_count, match_threshold, query_embedding or with a single unnamed json/jsonb parameter, but no matches were found in the schema cache.'}", "process_id": 8656, "thread_name": "MainThread", "filename": "rag_data_agent_v4.py", "line_number": 399, "function": "_search_rag_context"}
{"timestamp": "2025-10-18T21:10:08.139745Z", "level": "ERROR", "logger": "src.agent.rag_data_agent_v4", "message": "❌ Erro no query_v4: 'NoneType' object has no attribute 'invoke'", "process_id": 8656, "thread_name": "MainThread", "filename": "rag_data_agent_v4.py", "line_number": 341, "function": "query_v4", "exception": {"type": "AttributeError", "message": "'NoneType' object has no attribute 'invoke'", "traceback": "Traceback (most recent call last):\n  File \"C:\\workstashion\\eda-aiminds-i2a2-rb\\src\\agent\\rag_data_agent_v4.py\", line 282, in query_v4\n    response = self.llm.invoke(messages)\n               ^^^^^^^^^^^^^^^\nAttributeError: 'NoneType' object has no attribute 'invoke'"}}
{"timestamp": "2025-10-18T21:10:08.333737Z", "level": "ERROR", "logger": "agent.rag_data", "message": "Erro ao classificar intenção: 'NoneType' object has no attribute 'invoke'", "process_id": 8656, "thread_name": "MainThread", "filename": "intent_classifier.py", "line_number": 349, "function": "classify", "exception": {"type": "AttributeError", "message": "'NoneType' object has no attribute 'invoke'", "traceback": "Traceback (most recent call last):\n  File \"C:\\workstashion\\eda-aiminds-i2a2-rb\\src\\analysis\\intent_classifier.py\", line 310, in classify\n    response = self.llm.invoke(messages)\n               ^^^^^^^^^^^^^^^\nAttributeError: 'NoneType' object has no attribute 'invoke'"}}
{"timestamp": "2025-10-18T21:10:10.338712Z", "level": "ERROR", "logger": "src.agent.rag_data_agent_v4", "message": "❌ Erro na busca RAG: {'message': 'Could not find the function public.match_embeddings_v2(match_count, match_threshold, query_embedding) in the schema cache', 'code': 'PGRST202', 'hint': 'Perhaps you meant to call the function public.match_embeddings', 'details': 'Searched for the function public.match_embeddings_v2 with parameters match_count, match_threshold, query_embedding or with a single unnamed json/jsonb parameter, but no matches were found in the schema cache.'}", "process_id": 8656, "thread_name": "MainThread", "filename": "rag_data_agent_v4.py", "line_number": 399, "function": "_search_rag_context"}
{"timestamp": "2025-10-18T21:10:10.552719Z", "level": "ERROR", "logger": "src.agent.rag_data_agent_v4", "message": "❌ Erro no query_v4: 'NoneType' object has no attribute 'invoke'", "process_id": 8656, "thread_name": "MainThread", "filename": "rag_data_agent_v4.py", "line_number": 341, "function": "query_v4", "exception": {"type": "AttributeError", "message": "'NoneType' object has no attribute 'invoke'", "traceback": "Traceback (most recent call last):\n  File \"C:\\workstashion\\eda-aiminds-i2a2-rb\\src\\agent\\rag_data_agent_v4.py\", line 282, in query_v4\n    response = self.llm.invoke(messages)\n               ^^^^^^^^^^^^^^^\nAttributeError: 'NoneType' object has no attribute 'invoke'"}}
{"timestamp": "2025-10-18T21:10:10.683718Z", "level": "ERROR", "logger": "agent.rag_data", "message": "Erro ao classificar intenção: 'NoneType' object has no attribute 'invoke'", "process_id": 8656, "thread_name": "MainThread", "filename": "intent_classifier.py", "line_number": 349, "function": "classify", "exception": {"type": "AttributeError", "message": "'NoneType' object has no attribute 'invoke'", "traceback": "Traceback (most recent call last):\n  File \"C:\\workstashion\\eda-aiminds-i2a2-rb\\src\\analysis\\intent_classifier.py\", line 310, in classify\n    response = self.llm.invoke(messages)\n               ^^^^^^^^^^^^^^^\nAttributeError: 'NoneType' object has no attribute 'invoke'"}}
{"timestamp": "2025-10-18T21:10:12.455353Z", "level": "ERROR", "logger": "src.agent.rag_data_agent_v4", "message": "❌ Erro na busca RAG: {'message': 'Could not find the function public.match_embeddings_v2(match_count, match_threshold, query_embedding) in the schema cache', 'code': 'PGRST202', 'hint': 'Perhaps you meant to call the function public.match_embeddings', 'details': 'Searched for the function public.match_embeddings_v2 with parameters match_count, match_threshold, query_embedding or with a single unnamed json/jsonb parameter, but no matches were found in the schema cache.'}", "process_id": 8656, "thread_name": "MainThread", "filename": "rag_data_agent_v4.py", "line_number": 399, "function": "_search_rag_context"}
{"timestamp": "2025-10-18T21:10:12.668751Z", "level": "ERROR", "logger": "src.agent.rag_data_agent_v4", "message": "❌ Erro no query_v4: 'NoneType' object has no attribute 'invoke'", "process_id": 8656, "thread_name": "MainThread", "filename": "rag_data_agent_v4.py", "line_number": 341, "function": "query_v4", "exception": {"type": "AttributeError", "message": "'NoneType' object has no attribute 'invoke'", "traceback": "Traceback (most recent call last):\n  File \"C:\\workstashion\\eda-aiminds-i2a2-rb\\src\\agent\\rag_data_agent_v4.py\", line 282, in query_v4\n    response = self.llm.invoke(messages)\n               ^^^^^^^^^^^^^^^\nAttributeError: 'NoneType' object has no attribute 'invoke'"}}
{"timestamp": "2025-10-18T21:10:12.856746Z", "level": "ERROR", "logger": "agent.rag_data", "message": "Erro ao classificar intenção: 'NoneType' object has no attribute 'invoke'", "process_id": 8656, "thread_name": "MainThread", "filename": "intent_classifier.py", "line_number": 349, "function": "classify", "exception": {"type": "AttributeError", "message": "'NoneType' object has no attribute 'invoke'", "traceback": "Traceback (most recent call last):\n  File \"C:\\workstashion\\eda-aiminds-i2a2-rb\\src\\analysis\\intent_classifier.py\", line 310, in classify\n    response = self.llm.invoke(messages)\n               ^^^^^^^^^^^^^^^\nAttributeError: 'NoneType' object has no attribute 'invoke'"}}
{"timestamp": "2025-10-18T21:10:14.489734Z", "level": "ERROR", "logger": "src.agent.rag_data_agent_v4", "message": "❌ Erro na busca RAG: {'message': 'Could not find the function public.match_embeddings_v2(match_count, match_threshold, query_embedding) in the schema cache', 'code': 'PGRST202', 'hint': 'Perhaps you meant to call the function public.match_embeddings', 'details': 'Searched for the function public.match_embeddings_v2 with parameters match_count, match_threshold, query_embedding or with a single unnamed json/jsonb parameter, but no matches were found in the schema cache.'}", "process_id": 8656, "thread_name": "MainThread", "filename": "rag_data_agent_v4.py", "line_number": 399, "function": "_search_rag_context"}
{"timestamp": "2025-10-18T21:10:14.710731Z", "level": "ERROR", "logger": "src.agent.rag_data_agent_v4", "message": "❌ Erro no query_v4: 'NoneType' object has no attribute 'invoke'", "process_id": 8656, "thread_name": "MainThread", "filename": "rag_data_agent_v4.py", "line_number": 341, "function": "query_v4", "exception": {"type": "AttributeError", "message": "'NoneType' object has no attribute 'invoke'", "traceback": "Traceback (most recent call last):\n  File \"C:\\workstashion\\eda-aiminds-i2a2-rb\\src\\agent\\rag_data_agent_v4.py\", line 282, in query_v4\n    response = self.llm.invoke(messages)\n               ^^^^^^^^^^^^^^^\nAttributeError: 'NoneType' object has no attribute 'invoke'"}}
{"timestamp": "2025-10-18T21:10:14.809730Z", "level": "ERROR", "logger": "agent.rag_data", "message": "Erro ao classificar intenção: 'NoneType' object has no attribute 'invoke'", "process_id": 8656, "thread_name": "MainThread", "filename": "intent_classifier.py", "line_number": 349, "function": "classify", "exception": {"type": "AttributeError", "message": "'NoneType' object has no attribute 'invoke'", "traceback": "Traceback (most recent call last):\n  File \"C:\\workstashion\\eda-aiminds-i2a2-rb\\src\\analysis\\intent_classifier.py\", line 310, in classify\n    response = self.llm.invoke(messages)\n               ^^^^^^^^^^^^^^^\nAttributeError: 'NoneType' object has no attribute 'invoke'"}}
{"timestamp": "2025-10-18T21:10:16.417836Z", "level": "ERROR", "logger": "src.agent.rag_data_agent_v4", "message": "❌ Erro na busca RAG: {'message': 'Could not find the function public.match_embeddings_v2(match_count, match_threshold, query_embedding) in the schema cache', 'code': 'PGRST202', 'hint': 'Perhaps you meant to call the function public.match_embeddings', 'details': 'Searched for the function public.match_embeddings_v2 with parameters match_count, match_threshold, query_embedding or with a single unnamed json/jsonb parameter, but no matches were found in the schema cache.'}", "process_id": 8656, "thread_name": "MainThread", "filename": "rag_data_agent_v4.py", "line_number": 399, "function": "_search_rag_context"}
{"timestamp": "2025-10-18T21:10:16.629833Z", "level": "ERROR", "logger": "src.agent.rag_data_agent_v4", "message": "❌ Erro no query_v4: 'NoneType' object has no attribute 'invoke'", "process_id": 8656, "thread_name": "MainThread", "filename": "rag_data_agent_v4.py", "line_number": 341, "function": "query_v4", "exception": {"type": "AttributeError", "message": "'NoneType' object has no attribute 'invoke'", "traceback": "Traceback (most recent call last):\n  File \"C:\\workstashion\\eda-aiminds-i2a2-rb\\src\\agent\\rag_data_agent_v4.py\", line 282, in query_v4\n    response = self.llm.invoke(messages)\n               ^^^^^^^^^^^^^^^\nAttributeError: 'NoneType' object has no attribute 'invoke'"}}
{"timestamp": "2025-10-18T21:10:16.702834Z", "level": "ERROR", "logger": "agent.rag_data", "message": "Erro ao classificar intenção: 'NoneType' object has no attribute 'invoke'", "process_id": 8656, "thread_name": "MainThread", "filename": "intent_classifier.py", "line_number": 349, "function": "classify", "exception": {"type": "AttributeError", "message": "'NoneType' object has no attribute 'invoke'", "traceback": "Traceback (most recent call last):\n  File \"C:\\workstashion\\eda-aiminds-i2a2-rb\\src\\analysis\\intent_classifier.py\", line 310, in classify\n    response = self.llm.invoke(messages)\n               ^^^^^^^^^^^^^^^\nAttributeError: 'NoneType' object has no attribute 'invoke'"}}
{"timestamp": "2025-10-18T21:10:17.839168Z", "level": "ERROR", "logger": "src.agent.rag_data_agent_v4", "message": "❌ Erro na busca RAG: {'message': 'Could not find the function public.match_embeddings_v2(match_count, match_threshold, query_embedding) in the schema cache', 'code': 'PGRST202', 'hint': 'Perhaps you meant to call the function public.match_embeddings', 'details': 'Searched for the function public.match_embeddings_v2 with parameters match_count, match_threshold, query_embedding or with a single unnamed json/jsonb parameter, but no matches were found in the schema cache.'}", "process_id": 8656, "thread_name": "MainThread", "filename": "rag_data_agent_v4.py", "line_number": 399, "function": "_search_rag_context"}
{"timestamp": "2025-10-18T21:10:18.061160Z", "level": "ERROR", "logger": "src.agent.rag_data_agent_v4", "message": "❌ Erro no query_v4: 'NoneType' object has no attribute 'invoke'", "process_id": 8656, "thread_name": "MainThread", "filename": "rag_data_agent_v4.py", "line_number": 341, "function": "query_v4", "exception": {"type": "AttributeError", "message": "'NoneType' object has no attribute 'invoke'", "traceback": "Traceback (most recent call last):\n  File \"C:\\workstashion\\eda-aiminds-i2a2-rb\\src\\agent\\rag_data_agent_v4.py\", line 282, in query_v4\n    response = self.llm.invoke(messages)\n               ^^^^^^^^^^^^^^^\nAttributeError: 'NoneType' object has no attribute 'invoke'"}}
{"timestamp": "2025-10-18T21:10:18.150160Z", "level": "ERROR", "logger": "agent.rag_data", "message": "Erro ao classificar intenção: 'NoneType' object has no attribute 'invoke'", "process_id": 8656, "thread_name": "MainThread", "filename": "intent_classifier.py", "line_number": 349, "function": "classify", "exception": {"type": "AttributeError", "message": "'NoneType' object has no attribute 'invoke'", "traceback": "Traceback (most recent call last):\n  File \"C:\\workstashion\\eda-aiminds-i2a2-rb\\src\\analysis\\intent_classifier.py\", line 310, in classify\n    response = self.llm.invoke(messages)\n               ^^^^^^^^^^^^^^^\nAttributeError: 'NoneType' object has no attribute 'invoke'"}}
{"timestamp": "2025-10-18T21:10:19.424913Z", "level": "ERROR", "logger": "src.agent.rag_data_agent_v4", "message": "❌ Erro na busca RAG: {'message': 'Could not find the function public.match_embeddings_v2(match_count, match_threshold, query_embedding) in the schema cache', 'code': 'PGRST202', 'hint': 'Perhaps you meant to call the function public.match_embeddings', 'details': 'Searched for the function public.match_embeddings_v2 with parameters match_count, match_threshold, query_embedding or with a single unnamed json/jsonb parameter, but no matches were found in the schema cache.'}", "process_id": 8656, "thread_name": "MainThread", "filename": "rag_data_agent_v4.py", "line_number": 399, "function": "_search_rag_context"}
{"timestamp": "2025-10-18T21:10:19.647906Z", "level": "ERROR", "logger": "src.agent.rag_data_agent_v4", "message": "❌ Erro no query_v4: 'NoneType' object has no attribute 'invoke'", "process_id": 8656, "thread_name": "MainThread", "filename": "rag_data_agent_v4.py", "line_number": 341, "function": "query_v4", "exception": {"type": "AttributeError", "message": "'NoneType' object has no attribute 'invoke'", "traceback": "Traceback (most recent call last):\n  File \"C:\\workstashion\\eda-aiminds-i2a2-rb\\src\\agent\\rag_data_agent_v4.py\", line 282, in query_v4\n    response = self.llm.invoke(messages)\n               ^^^^^^^^^^^^^^^\nAttributeError: 'NoneType' object has no attribute 'invoke'"}}
{"timestamp": "2025-10-18T21:10:19.733906Z", "level": "ERROR", "logger": "agent.rag_data", "message": "Erro ao classificar intenção: 'NoneType' object has no attribute 'invoke'", "process_id": 8656, "thread_name": "MainThread", "filename": "intent_classifier.py", "line_number": 349, "function": "classify", "exception": {"type": "AttributeError", "message": "'NoneType' object has no attribute 'invoke'", "traceback": "Traceback (most recent call last):\n  File \"C:\\workstashion\\eda-aiminds-i2a2-rb\\src\\analysis\\intent_classifier.py\", line 310, in classify\n    response = self.llm.invoke(messages)\n               ^^^^^^^^^^^^^^^\nAttributeError: 'NoneType' object has no attribute 'invoke'"}}
{"timestamp": "2025-10-18T21:10:20.922986Z", "level": "ERROR", "logger": "src.agent.rag_data_agent_v4", "message": "❌ Erro na busca RAG: {'message': 'Could not find the function public.match_embeddings_v2(match_count, match_threshold, query_embedding) in the schema cache', 'code': 'PGRST202', 'hint': 'Perhaps you meant to call the function public.match_embeddings', 'details': 'Searched for the function public.match_embeddings_v2 with parameters match_count, match_threshold, query_embedding or with a single unnamed json/jsonb parameter, but no matches were found in the schema cache.'}", "process_id": 8656, "thread_name": "MainThread", "filename": "rag_data_agent_v4.py", "line_number": 399, "function": "_search_rag_context"}
{"timestamp": "2025-10-18T21:10:21.134984Z", "level": "ERROR", "logger": "src.agent.rag_data_agent_v4", "message": "❌ Erro no query_v4: 'NoneType' object has no attribute 'invoke'", "process_id": 8656, "thread_name": "MainThread", "filename": "rag_data_agent_v4.py", "line_number": 341, "function": "query_v4", "exception": {"type": "AttributeError", "message": "'NoneType' object has no attribute 'invoke'", "traceback": "Traceback (most recent call last):\n  File \"C:\\workstashion\\eda-aiminds-i2a2-rb\\src\\agent\\rag_data_agent_v4.py\", line 282, in query_v4\n    response = self.llm.invoke(messages)\n               ^^^^^^^^^^^^^^^\nAttributeError: 'NoneType' object has no attribute 'invoke'"}}
{"timestamp": "2025-10-18T21:10:21.242984Z", "level": "ERROR", "logger": "agent.rag_data", "message": "Erro ao classificar intenção: 'NoneType' object has no attribute 'invoke'", "process_id": 8656, "thread_name": "MainThread", "filename": "intent_classifier.py", "line_number": 349, "function": "classify", "exception": {"type": "AttributeError", "message": "'NoneType' object has no attribute 'invoke'", "traceback": "Traceback (most recent call last):\n  File \"C:\\workstashion\\eda-aiminds-i2a2-rb\\src\\analysis\\intent_classifier.py\", line 310, in classify\n    response = self.llm.invoke(messages)\n               ^^^^^^^^^^^^^^^\nAttributeError: 'NoneType' object has no attribute 'invoke'"}}
{"timestamp": "2025-10-18T21:10:22.726544Z", "level": "ERROR", "logger": "src.agent.rag_data_agent_v4", "message": "❌ Erro na busca RAG: {'message': 'Could not find the function public.match_embeddings_v2(match_count, match_threshold, query_embedding) in the schema cache', 'code': 'PGRST202', 'hint': 'Perhaps you meant to call the function public.match_embeddings', 'details': 'Searched for the function public.match_embeddings_v2 with parameters match_count, match_threshold, query_embedding or with a single unnamed json/jsonb parameter, but no matches were found in the schema cache.'}", "process_id": 8656, "thread_name": "MainThread", "filename": "rag_data_agent_v4.py", "line_number": 399, "function": "_search_rag_context"}
{"timestamp": "2025-10-18T21:10:23.010536Z", "level": "ERROR", "logger": "src.agent.rag_data_agent_v4", "message": "❌ Erro no query_v4: 'NoneType' object has no attribute 'invoke'", "process_id": 8656, "thread_name": "MainThread", "filename": "rag_data_agent_v4.py", "line_number": 341, "function": "query_v4", "exception": {"type": "AttributeError", "message": "'NoneType' object has no attribute 'invoke'", "traceback": "Traceback (most recent call last):\n  File \"C:\\workstashion\\eda-aiminds-i2a2-rb\\src\\agent\\rag_data_agent_v4.py\", line 282, in query_v4\n    response = self.llm.invoke(messages)\n               ^^^^^^^^^^^^^^^\nAttributeError: 'NoneType' object has no attribute 'invoke'"}}
{"timestamp": "2025-10-18T21:10:24.058849Z", "level": "ERROR", "logger": "agent.rag_data", "message": "Erro ao classificar intenção: 'NoneType' object has no attribute 'invoke'", "process_id": 8656, "thread_name": "MainThread", "filename": "intent_classifier.py", "line_number": 349, "function": "classify", "exception": {"type": "AttributeError", "message": "'NoneType' object has no attribute 'invoke'", "traceback": "Traceback (most recent call last):\n  File \"C:\\workstashion\\eda-aiminds-i2a2-rb\\src\\analysis\\intent_classifier.py\", line 310, in classify\n    response = self.llm.invoke(messages)\n               ^^^^^^^^^^^^^^^\nAttributeError: 'NoneType' object has no attribute 'invoke'"}}
{"timestamp": "2025-10-18T21:10:25.895170Z", "level": "ERROR", "logger": "src.agent.rag_data_agent_v4", "message": "❌ Erro na busca RAG: {'message': 'Could not find the function public.match_embeddings_v2(match_count, match_threshold, query_embedding) in the schema cache', 'code': 'PGRST202', 'hint': 'Perhaps you meant to call the function public.match_embeddings', 'details': 'Searched for the function public.match_embeddings_v2 with parameters match_count, match_threshold, query_embedding or with a single unnamed json/jsonb parameter, but no matches were found in the schema cache.'}", "process_id": 8656, "thread_name": "MainThread", "filename": "rag_data_agent_v4.py", "line_number": 399, "function": "_search_rag_context"}
{"timestamp": "2025-10-18T21:10:26.222172Z", "level": "ERROR", "logger": "src.agent.rag_data_agent_v4", "message": "❌ Erro no query_v4: 'NoneType' object has no attribute 'invoke'", "process_id": 8656, "thread_name": "MainThread", "filename": "rag_data_agent_v4.py", "line_number": 341, "function": "query_v4", "exception": {"type": "AttributeError", "message": "'NoneType' object has no attribute 'invoke'", "traceback": "Traceback (most recent call last):\n  File \"C:\\workstashion\\eda-aiminds-i2a2-rb\\src\\agent\\rag_data_agent_v4.py\", line 282, in query_v4\n    response = self.llm.invoke(messages)\n               ^^^^^^^^^^^^^^^\nAttributeError: 'NoneType' object has no attribute 'invoke'"}}
{"timestamp": "2025-10-18T21:17:10.933964Z", "level": "ERROR", "logger": "agent.rag_data", "message": "Erro ao classificar intenção: Extra data: line 12 column 1 (char 535)", "process_id": 7968, "thread_name": "MainThread", "filename": "intent_classifier.py", "line_number": 349, "function": "classify", "exception": {"type": "JSONDecodeError", "message": "Extra data: line 12 column 1 (char 535)", "traceback": "Traceback (most recent call last):\n  File \"C:\\workstashion\\eda-aiminds-i2a2-rb\\src\\analysis\\intent_classifier.py\", line 321, in classify\n    classification = json.loads(response_text)\n                     ^^^^^^^^^^^^^^^^^^^^^^^^^\n  File \"C:\\Python312\\Lib\\json\\__init__.py\", line 346, in loads\n    return _default_decoder.decode(s)\n           ^^^^^^^^^^^^^^^^^^^^^^^^^^\n  File \"C:\\Python312\\Lib\\json\\decoder.py\", line 340, in decode\n    raise JSONDecodeError(\"Extra data\", s, end)\njson.decoder.JSONDecodeError: Extra data: line 12 column 1 (char 535)"}}
{"timestamp": "2025-10-18T21:17:13.174933Z", "level": "ERROR", "logger": "src.agent.rag_data_agent_v4", "message": "❌ Erro na busca RAG: {'message': 'Could not find the function public.match_embeddings_v2(match_count, match_threshold, query_embedding) in the schema cache', 'code': 'PGRST202', 'hint': 'Perhaps you meant to call the function public.match_embeddings', 'details': 'Searched for the function public.match_embeddings_v2 with parameters match_count, match_threshold, query_embedding or with a single unnamed json/jsonb parameter, but no matches were found in the schema cache.'}", "process_id": 7968, "thread_name": "MainThread", "filename": "rag_data_agent_v4.py", "line_number": 468, "function": "_search_rag_context"}
{"timestamp": "2025-10-18T21:17:23.487588Z", "level": "ERROR", "logger": "agent.rag_data", "message": "Erro ao classificar intenção: Extra data: line 12 column 1 (char 520)", "process_id": 7968, "thread_name": "MainThread", "filename": "intent_classifier.py", "line_number": 349, "function": "classify", "exception": {"type": "JSONDecodeError", "message": "Extra data: line 12 column 1 (char 520)", "traceback": "Traceback (most recent call last):\n  File \"C:\\workstashion\\eda-aiminds-i2a2-rb\\src\\analysis\\intent_classifier.py\", line 321, in classify\n    classification = json.loads(response_text)\n                     ^^^^^^^^^^^^^^^^^^^^^^^^^\n  File \"C:\\Python312\\Lib\\json\\__init__.py\", line 346, in loads\n    return _default_decoder.decode(s)\n           ^^^^^^^^^^^^^^^^^^^^^^^^^^\n  File \"C:\\Python312\\Lib\\json\\decoder.py\", line 340, in decode\n    raise JSONDecodeError(\"Extra data\", s, end)\njson.decoder.JSONDecodeError: Extra data: line 12 column 1 (char 520)"}}
{"timestamp": "2025-10-18T21:17:26.279680Z", "level": "ERROR", "logger": "src.agent.rag_data_agent_v4", "message": "❌ Erro na busca RAG: {'message': 'Could not find the function public.match_embeddings_v2(match_count, match_threshold, query_embedding) in the schema cache', 'code': 'PGRST202', 'hint': 'Perhaps you meant to call the function public.match_embeddings', 'details': 'Searched for the function public.match_embeddings_v2 with parameters match_count, match_threshold, query_embedding or with a single unnamed json/jsonb parameter, but no matches were found in the schema cache.'}", "process_id": 7968, "thread_name": "MainThread", "filename": "rag_data_agent_v4.py", "line_number": 468, "function": "_search_rag_context"}
{"timestamp": "2025-10-18T21:18:05.762950Z", "level": "ERROR", "logger": "agent.rag_data", "message": "Erro ao classificar intenção: Expecting value: line 1 column 1 (char 0)", "process_id": 7968, "thread_name": "MainThread", "filename": "intent_classifier.py", "line_number": 349, "function": "classify", "exception": {"type": "JSONDecodeError", "message": "Expecting value: line 1 column 1 (char 0)", "traceback": "Traceback (most recent call last):\n  File \"C:\\workstashion\\eda-aiminds-i2a2-rb\\src\\analysis\\intent_classifier.py\", line 321, in classify\n    classification = json.loads(response_text)\n                     ^^^^^^^^^^^^^^^^^^^^^^^^^\n  File \"C:\\Python312\\Lib\\json\\__init__.py\", line 346, in loads\n    return _default_decoder.decode(s)\n           ^^^^^^^^^^^^^^^^^^^^^^^^^^\n  File \"C:\\Python312\\Lib\\json\\decoder.py\", line 337, in decode\n    obj, end = self.raw_decode(s, idx=_w(s, 0).end())\n               ^^^^^^^^^^^^^^^^^^^^^^^^^^^^^^^^^^^^^^\n  File \"C:\\Python312\\Lib\\json\\decoder.py\", line 355, in raw_decode\n    raise JSONDecodeError(\"Expecting value\", s, err.value) from None\njson.decoder.JSONDecodeError: Expecting value: line 1 column 1 (char 0)"}}
{"timestamp": "2025-10-18T21:18:08.508107Z", "level": "ERROR", "logger": "src.agent.rag_data_agent_v4", "message": "❌ Erro na busca RAG: {'message': 'Could not find the function public.match_embeddings_v2(match_count, match_threshold, query_embedding) in the schema cache', 'code': 'PGRST202', 'hint': 'Perhaps you meant to call the function public.match_embeddings', 'details': 'Searched for the function public.match_embeddings_v2 with parameters match_count, match_threshold, query_embedding or with a single unnamed json/jsonb parameter, but no matches were found in the schema cache.'}", "process_id": 7968, "thread_name": "MainThread", "filename": "rag_data_agent_v4.py", "line_number": 468, "function": "_search_rag_context"}
{"timestamp": "2025-10-18T21:18:47.732741Z", "level": "ERROR", "logger": "agent.rag_data", "message": "Erro ao classificar intenção: Expecting value: line 1 column 1 (char 0)", "process_id": 7968, "thread_name": "MainThread", "filename": "intent_classifier.py", "line_number": 349, "function": "classify", "exception": {"type": "JSONDecodeError", "message": "Expecting value: line 1 column 1 (char 0)", "traceback": "Traceback (most recent call last):\n  File \"C:\\workstashion\\eda-aiminds-i2a2-rb\\src\\analysis\\intent_classifier.py\", line 321, in classify\n    classification = json.loads(response_text)\n                     ^^^^^^^^^^^^^^^^^^^^^^^^^\n  File \"C:\\Python312\\Lib\\json\\__init__.py\", line 346, in loads\n    return _default_decoder.decode(s)\n           ^^^^^^^^^^^^^^^^^^^^^^^^^^\n  File \"C:\\Python312\\Lib\\json\\decoder.py\", line 337, in decode\n    obj, end = self.raw_decode(s, idx=_w(s, 0).end())\n               ^^^^^^^^^^^^^^^^^^^^^^^^^^^^^^^^^^^^^^\n  File \"C:\\Python312\\Lib\\json\\decoder.py\", line 355, in raw_decode\n    raise JSONDecodeError(\"Expecting value\", s, err.value) from None\njson.decoder.JSONDecodeError: Expecting value: line 1 column 1 (char 0)"}}
{"timestamp": "2025-10-18T21:18:50.176448Z", "level": "ERROR", "logger": "src.agent.rag_data_agent_v4", "message": "❌ Erro na busca RAG: {'message': 'Could not find the function public.match_embeddings_v2(match_count, match_threshold, query_embedding) in the schema cache', 'code': 'PGRST202', 'hint': 'Perhaps you meant to call the function public.match_embeddings', 'details': 'Searched for the function public.match_embeddings_v2 with parameters match_count, match_threshold, query_embedding or with a single unnamed json/jsonb parameter, but no matches were found in the schema cache.'}", "process_id": 7968, "thread_name": "MainThread", "filename": "rag_data_agent_v4.py", "line_number": 468, "function": "_search_rag_context"}
{"timestamp": "2025-10-18T21:19:28.823151Z", "level": "ERROR", "logger": "agent.rag_data", "message": "Erro ao classificar intenção: Extra data: line 12 column 1 (char 548)", "process_id": 7968, "thread_name": "MainThread", "filename": "intent_classifier.py", "line_number": 349, "function": "classify", "exception": {"type": "JSONDecodeError", "message": "Extra data: line 12 column 1 (char 548)", "traceback": "Traceback (most recent call last):\n  File \"C:\\workstashion\\eda-aiminds-i2a2-rb\\src\\analysis\\intent_classifier.py\", line 321, in classify\n    classification = json.loads(response_text)\n                     ^^^^^^^^^^^^^^^^^^^^^^^^^\n  File \"C:\\Python312\\Lib\\json\\__init__.py\", line 346, in loads\n    return _default_decoder.decode(s)\n           ^^^^^^^^^^^^^^^^^^^^^^^^^^\n  File \"C:\\Python312\\Lib\\json\\decoder.py\", line 340, in decode\n    raise JSONDecodeError(\"Extra data\", s, end)\njson.decoder.JSONDecodeError: Extra data: line 12 column 1 (char 548)"}}
{"timestamp": "2025-10-18T21:19:31.071366Z", "level": "ERROR", "logger": "src.agent.rag_data_agent_v4", "message": "❌ Erro na busca RAG: {'message': 'Could not find the function public.match_embeddings_v2(match_count, match_threshold, query_embedding) in the schema cache', 'code': 'PGRST202', 'hint': 'Perhaps you meant to call the function public.match_embeddings', 'details': 'Searched for the function public.match_embeddings_v2 with parameters match_count, match_threshold, query_embedding or with a single unnamed json/jsonb parameter, but no matches were found in the schema cache.'}", "process_id": 7968, "thread_name": "MainThread", "filename": "rag_data_agent_v4.py", "line_number": 468, "function": "_search_rag_context"}
{"timestamp": "2025-10-18T21:20:10.175836Z", "level": "ERROR", "logger": "agent.rag_data", "message": "Erro ao classificar intenção: Expecting value: line 1 column 1 (char 0)", "process_id": 7968, "thread_name": "MainThread", "filename": "intent_classifier.py", "line_number": 349, "function": "classify", "exception": {"type": "JSONDecodeError", "message": "Expecting value: line 1 column 1 (char 0)", "traceback": "Traceback (most recent call last):\n  File \"C:\\workstashion\\eda-aiminds-i2a2-rb\\src\\analysis\\intent_classifier.py\", line 321, in classify\n    classification = json.loads(response_text)\n                     ^^^^^^^^^^^^^^^^^^^^^^^^^\n  File \"C:\\Python312\\Lib\\json\\__init__.py\", line 346, in loads\n    return _default_decoder.decode(s)\n           ^^^^^^^^^^^^^^^^^^^^^^^^^^\n  File \"C:\\Python312\\Lib\\json\\decoder.py\", line 337, in decode\n    obj, end = self.raw_decode(s, idx=_w(s, 0).end())\n               ^^^^^^^^^^^^^^^^^^^^^^^^^^^^^^^^^^^^^^\n  File \"C:\\Python312\\Lib\\json\\decoder.py\", line 355, in raw_decode\n    raise JSONDecodeError(\"Expecting value\", s, err.value) from None\njson.decoder.JSONDecodeError: Expecting value: line 1 column 1 (char 0)"}}
{"timestamp": "2025-10-18T21:20:12.581371Z", "level": "ERROR", "logger": "src.agent.rag_data_agent_v4", "message": "❌ Erro na busca RAG: {'message': 'Could not find the function public.match_embeddings_v2(match_count, match_threshold, query_embedding) in the schema cache', 'code': 'PGRST202', 'hint': 'Perhaps you meant to call the function public.match_embeddings', 'details': 'Searched for the function public.match_embeddings_v2 with parameters match_count, match_threshold, query_embedding or with a single unnamed json/jsonb parameter, but no matches were found in the schema cache.'}", "process_id": 7968, "thread_name": "MainThread", "filename": "rag_data_agent_v4.py", "line_number": 468, "function": "_search_rag_context"}
{"timestamp": "2025-10-18T21:20:50.900353Z", "level": "ERROR", "logger": "agent.rag_data", "message": "Erro ao classificar intenção: Extra data: line 12 column 1 (char 437)", "process_id": 7968, "thread_name": "MainThread", "filename": "intent_classifier.py", "line_number": 349, "function": "classify", "exception": {"type": "JSONDecodeError", "message": "Extra data: line 12 column 1 (char 437)", "traceback": "Traceback (most recent call last):\n  File \"C:\\workstashion\\eda-aiminds-i2a2-rb\\src\\analysis\\intent_classifier.py\", line 321, in classify\n    classification = json.loads(response_text)\n                     ^^^^^^^^^^^^^^^^^^^^^^^^^\n  File \"C:\\Python312\\Lib\\json\\__init__.py\", line 346, in loads\n    return _default_decoder.decode(s)\n           ^^^^^^^^^^^^^^^^^^^^^^^^^^\n  File \"C:\\Python312\\Lib\\json\\decoder.py\", line 340, in decode\n    raise JSONDecodeError(\"Extra data\", s, end)\njson.decoder.JSONDecodeError: Extra data: line 12 column 1 (char 437)"}}
{"timestamp": "2025-10-18T21:20:53.247792Z", "level": "ERROR", "logger": "src.agent.rag_data_agent_v4", "message": "❌ Erro na busca RAG: {'message': 'Could not find the function public.match_embeddings_v2(match_count, match_threshold, query_embedding) in the schema cache', 'code': 'PGRST202', 'hint': 'Perhaps you meant to call the function public.match_embeddings', 'details': 'Searched for the function public.match_embeddings_v2 with parameters match_count, match_threshold, query_embedding or with a single unnamed json/jsonb parameter, but no matches were found in the schema cache.'}", "process_id": 7968, "thread_name": "MainThread", "filename": "rag_data_agent_v4.py", "line_number": 468, "function": "_search_rag_context"}
{"timestamp": "2025-10-18T21:21:31.836291Z", "level": "ERROR", "logger": "agent.rag_data", "message": "Erro ao classificar intenção: Extra data: line 12 column 1 (char 508)", "process_id": 7968, "thread_name": "MainThread", "filename": "intent_classifier.py", "line_number": 349, "function": "classify", "exception": {"type": "JSONDecodeError", "message": "Extra data: line 12 column 1 (char 508)", "traceback": "Traceback (most recent call last):\n  File \"C:\\workstashion\\eda-aiminds-i2a2-rb\\src\\analysis\\intent_classifier.py\", line 321, in classify\n    classification = json.loads(response_text)\n                     ^^^^^^^^^^^^^^^^^^^^^^^^^\n  File \"C:\\Python312\\Lib\\json\\__init__.py\", line 346, in loads\n    return _default_decoder.decode(s)\n           ^^^^^^^^^^^^^^^^^^^^^^^^^^\n  File \"C:\\Python312\\Lib\\json\\decoder.py\", line 340, in decode\n    raise JSONDecodeError(\"Extra data\", s, end)\njson.decoder.JSONDecodeError: Extra data: line 12 column 1 (char 508)"}}
{"timestamp": "2025-10-18T21:21:34.699817Z", "level": "ERROR", "logger": "src.agent.rag_data_agent_v4", "message": "❌ Erro na busca RAG: {'message': 'Could not find the function public.match_embeddings_v2(match_count, match_threshold, query_embedding) in the schema cache', 'code': 'PGRST202', 'hint': 'Perhaps you meant to call the function public.match_embeddings', 'details': 'Searched for the function public.match_embeddings_v2 with parameters match_count, match_threshold, query_embedding or with a single unnamed json/jsonb parameter, but no matches were found in the schema cache.'}", "process_id": 7968, "thread_name": "MainThread", "filename": "rag_data_agent_v4.py", "line_number": 468, "function": "_search_rag_context"}
{"timestamp": "2025-10-18T21:22:13.010623Z", "level": "ERROR", "logger": "agent.rag_data", "message": "Erro ao classificar intenção: Extra data: line 12 column 1 (char 414)", "process_id": 7968, "thread_name": "MainThread", "filename": "intent_classifier.py", "line_number": 349, "function": "classify", "exception": {"type": "JSONDecodeError", "message": "Extra data: line 12 column 1 (char 414)", "traceback": "Traceback (most recent call last):\n  File \"C:\\workstashion\\eda-aiminds-i2a2-rb\\src\\analysis\\intent_classifier.py\", line 321, in classify\n    classification = json.loads(response_text)\n                     ^^^^^^^^^^^^^^^^^^^^^^^^^\n  File \"C:\\Python312\\Lib\\json\\__init__.py\", line 346, in loads\n    return _default_decoder.decode(s)\n           ^^^^^^^^^^^^^^^^^^^^^^^^^^\n  File \"C:\\Python312\\Lib\\json\\decoder.py\", line 340, in decode\n    raise JSONDecodeError(\"Extra data\", s, end)\njson.decoder.JSONDecodeError: Extra data: line 12 column 1 (char 414)"}}
{"timestamp": "2025-10-18T21:22:14.298213Z", "level": "ERROR", "logger": "src.agent.rag_data_agent_v4", "message": "❌ Erro na busca RAG: {'message': 'Could not find the function public.match_embeddings_v2(match_count, match_threshold, query_embedding) in the schema cache', 'code': 'PGRST202', 'hint': 'Perhaps you meant to call the function public.match_embeddings', 'details': 'Searched for the function public.match_embeddings_v2 with parameters match_count, match_threshold, query_embedding or with a single unnamed json/jsonb parameter, but no matches were found in the schema cache.'}", "process_id": 7968, "thread_name": "MainThread", "filename": "rag_data_agent_v4.py", "line_number": 468, "function": "_search_rag_context"}
{"timestamp": "2025-10-18T21:22:50.839627Z", "level": "ERROR", "logger": "agent.rag_data", "message": "Erro ao classificar intenção: Expecting value: line 1 column 1 (char 0)", "process_id": 7968, "thread_name": "MainThread", "filename": "intent_classifier.py", "line_number": 349, "function": "classify", "exception": {"type": "JSONDecodeError", "message": "Expecting value: line 1 column 1 (char 0)", "traceback": "Traceback (most recent call last):\n  File \"C:\\workstashion\\eda-aiminds-i2a2-rb\\src\\analysis\\intent_classifier.py\", line 321, in classify\n    classification = json.loads(response_text)\n                     ^^^^^^^^^^^^^^^^^^^^^^^^^\n  File \"C:\\Python312\\Lib\\json\\__init__.py\", line 346, in loads\n    return _default_decoder.decode(s)\n           ^^^^^^^^^^^^^^^^^^^^^^^^^^\n  File \"C:\\Python312\\Lib\\json\\decoder.py\", line 337, in decode\n    obj, end = self.raw_decode(s, idx=_w(s, 0).end())\n               ^^^^^^^^^^^^^^^^^^^^^^^^^^^^^^^^^^^^^^\n  File \"C:\\Python312\\Lib\\json\\decoder.py\", line 355, in raw_decode\n    raise JSONDecodeError(\"Expecting value\", s, err.value) from None\njson.decoder.JSONDecodeError: Expecting value: line 1 column 1 (char 0)"}}
{"timestamp": "2025-10-18T21:22:53.501157Z", "level": "ERROR", "logger": "src.agent.rag_data_agent_v4", "message": "❌ Erro na busca RAG: {'message': 'Could not find the function public.match_embeddings_v2(match_count, match_threshold, query_embedding) in the schema cache', 'code': 'PGRST202', 'hint': 'Perhaps you meant to call the function public.match_embeddings', 'details': 'Searched for the function public.match_embeddings_v2 with parameters match_count, match_threshold, query_embedding or with a single unnamed json/jsonb parameter, but no matches were found in the schema cache.'}", "process_id": 7968, "thread_name": "MainThread", "filename": "rag_data_agent_v4.py", "line_number": 468, "function": "_search_rag_context"}
{"timestamp": "2025-10-18T21:23:33.165171Z", "level": "ERROR", "logger": "agent.rag_data", "message": "Erro ao classificar intenção: Expecting value: line 1 column 1 (char 0)", "process_id": 7968, "thread_name": "MainThread", "filename": "intent_classifier.py", "line_number": 349, "function": "classify", "exception": {"type": "JSONDecodeError", "message": "Expecting value: line 1 column 1 (char 0)", "traceback": "Traceback (most recent call last):\n  File \"C:\\workstashion\\eda-aiminds-i2a2-rb\\src\\analysis\\intent_classifier.py\", line 321, in classify\n    classification = json.loads(response_text)\n                     ^^^^^^^^^^^^^^^^^^^^^^^^^\n  File \"C:\\Python312\\Lib\\json\\__init__.py\", line 346, in loads\n    return _default_decoder.decode(s)\n           ^^^^^^^^^^^^^^^^^^^^^^^^^^\n  File \"C:\\Python312\\Lib\\json\\decoder.py\", line 337, in decode\n    obj, end = self.raw_decode(s, idx=_w(s, 0).end())\n               ^^^^^^^^^^^^^^^^^^^^^^^^^^^^^^^^^^^^^^\n  File \"C:\\Python312\\Lib\\json\\decoder.py\", line 355, in raw_decode\n    raise JSONDecodeError(\"Expecting value\", s, err.value) from None\njson.decoder.JSONDecodeError: Expecting value: line 1 column 1 (char 0)"}}
{"timestamp": "2025-10-18T21:23:35.488440Z", "level": "ERROR", "logger": "src.agent.rag_data_agent_v4", "message": "❌ Erro na busca RAG: {'message': 'Could not find the function public.match_embeddings_v2(match_count, match_threshold, query_embedding) in the schema cache', 'code': 'PGRST202', 'hint': 'Perhaps you meant to call the function public.match_embeddings', 'details': 'Searched for the function public.match_embeddings_v2 with parameters match_count, match_threshold, query_embedding or with a single unnamed json/jsonb parameter, but no matches were found in the schema cache.'}", "process_id": 7968, "thread_name": "MainThread", "filename": "rag_data_agent_v4.py", "line_number": 468, "function": "_search_rag_context"}
{"timestamp": "2025-10-18T21:24:14.336531Z", "level": "ERROR", "logger": "agent.rag_data", "message": "Erro ao classificar intenção: Expecting value: line 1 column 1 (char 0)", "process_id": 7968, "thread_name": "MainThread", "filename": "intent_classifier.py", "line_number": 349, "function": "classify", "exception": {"type": "JSONDecodeError", "message": "Expecting value: line 1 column 1 (char 0)", "traceback": "Traceback (most recent call last):\n  File \"C:\\workstashion\\eda-aiminds-i2a2-rb\\src\\analysis\\intent_classifier.py\", line 321, in classify\n    classification = json.loads(response_text)\n                     ^^^^^^^^^^^^^^^^^^^^^^^^^\n  File \"C:\\Python312\\Lib\\json\\__init__.py\", line 346, in loads\n    return _default_decoder.decode(s)\n           ^^^^^^^^^^^^^^^^^^^^^^^^^^\n  File \"C:\\Python312\\Lib\\json\\decoder.py\", line 337, in decode\n    obj, end = self.raw_decode(s, idx=_w(s, 0).end())\n               ^^^^^^^^^^^^^^^^^^^^^^^^^^^^^^^^^^^^^^\n  File \"C:\\Python312\\Lib\\json\\decoder.py\", line 355, in raw_decode\n    raise JSONDecodeError(\"Expecting value\", s, err.value) from None\njson.decoder.JSONDecodeError: Expecting value: line 1 column 1 (char 0)"}}
{"timestamp": "2025-10-18T21:24:15.753663Z", "level": "ERROR", "logger": "src.agent.rag_data_agent_v4", "message": "❌ Erro na busca RAG: {'message': 'Could not find the function public.match_embeddings_v2(match_count, match_threshold, query_embedding) in the schema cache', 'code': 'PGRST202', 'hint': 'Perhaps you meant to call the function public.match_embeddings', 'details': 'Searched for the function public.match_embeddings_v2 with parameters match_count, match_threshold, query_embedding or with a single unnamed json/jsonb parameter, but no matches were found in the schema cache.'}", "process_id": 7968, "thread_name": "MainThread", "filename": "rag_data_agent_v4.py", "line_number": 468, "function": "_search_rag_context"}
{"timestamp": "2025-10-18T21:24:53.957985Z", "level": "ERROR", "logger": "agent.rag_data", "message": "Erro ao classificar intenção: Extra data: line 12 column 1 (char 510)", "process_id": 7968, "thread_name": "MainThread", "filename": "intent_classifier.py", "line_number": 349, "function": "classify", "exception": {"type": "JSONDecodeError", "message": "Extra data: line 12 column 1 (char 510)", "traceback": "Traceback (most recent call last):\n  File \"C:\\workstashion\\eda-aiminds-i2a2-rb\\src\\analysis\\intent_classifier.py\", line 321, in classify\n    classification = json.loads(response_text)\n                     ^^^^^^^^^^^^^^^^^^^^^^^^^\n  File \"C:\\Python312\\Lib\\json\\__init__.py\", line 346, in loads\n    return _default_decoder.decode(s)\n           ^^^^^^^^^^^^^^^^^^^^^^^^^^\n  File \"C:\\Python312\\Lib\\json\\decoder.py\", line 340, in decode\n    raise JSONDecodeError(\"Extra data\", s, end)\njson.decoder.JSONDecodeError: Extra data: line 12 column 1 (char 510)"}}
{"timestamp": "2025-10-18T21:24:56.311218Z", "level": "ERROR", "logger": "src.agent.rag_data_agent_v4", "message": "❌ Erro na busca RAG: {'message': 'Could not find the function public.match_embeddings_v2(match_count, match_threshold, query_embedding) in the schema cache', 'code': 'PGRST202', 'hint': 'Perhaps you meant to call the function public.match_embeddings', 'details': 'Searched for the function public.match_embeddings_v2 with parameters match_count, match_threshold, query_embedding or with a single unnamed json/jsonb parameter, but no matches were found in the schema cache.'}", "process_id": 7968, "thread_name": "MainThread", "filename": "rag_data_agent_v4.py", "line_number": 468, "function": "_search_rag_context"}
{"timestamp": "2025-10-18T21:25:35.598330Z", "level": "ERROR", "logger": "agent.rag_data", "message": "Erro ao classificar intenção: Extra data: line 12 column 1 (char 484)", "process_id": 7968, "thread_name": "MainThread", "filename": "intent_classifier.py", "line_number": 349, "function": "classify", "exception": {"type": "JSONDecodeError", "message": "Extra data: line 12 column 1 (char 484)", "traceback": "Traceback (most recent call last):\n  File \"C:\\workstashion\\eda-aiminds-i2a2-rb\\src\\analysis\\intent_classifier.py\", line 321, in classify\n    classification = json.loads(response_text)\n                     ^^^^^^^^^^^^^^^^^^^^^^^^^\n  File \"C:\\Python312\\Lib\\json\\__init__.py\", line 346, in loads\n    return _default_decoder.decode(s)\n           ^^^^^^^^^^^^^^^^^^^^^^^^^^\n  File \"C:\\Python312\\Lib\\json\\decoder.py\", line 340, in decode\n    raise JSONDecodeError(\"Extra data\", s, end)\njson.decoder.JSONDecodeError: Extra data: line 12 column 1 (char 484)"}}
{"timestamp": "2025-10-18T21:25:38.356616Z", "level": "ERROR", "logger": "src.agent.rag_data_agent_v4", "message": "❌ Erro na busca RAG: {'message': 'Could not find the function public.match_embeddings_v2(match_count, match_threshold, query_embedding) in the schema cache', 'code': 'PGRST202', 'hint': 'Perhaps you meant to call the function public.match_embeddings', 'details': 'Searched for the function public.match_embeddings_v2 with parameters match_count, match_threshold, query_embedding or with a single unnamed json/jsonb parameter, but no matches were found in the schema cache.'}", "process_id": 7968, "thread_name": "MainThread", "filename": "rag_data_agent_v4.py", "line_number": 468, "function": "_search_rag_context"}
{"timestamp": "2025-10-18T21:26:17.683456Z", "level": "ERROR", "logger": "agent.rag_data", "message": "Erro ao classificar intenção: Expecting value: line 1 column 1 (char 0)", "process_id": 7968, "thread_name": "MainThread", "filename": "intent_classifier.py", "line_number": 349, "function": "classify", "exception": {"type": "JSONDecodeError", "message": "Expecting value: line 1 column 1 (char 0)", "traceback": "Traceback (most recent call last):\n  File \"C:\\workstashion\\eda-aiminds-i2a2-rb\\src\\analysis\\intent_classifier.py\", line 321, in classify\n    classification = json.loads(response_text)\n                     ^^^^^^^^^^^^^^^^^^^^^^^^^\n  File \"C:\\Python312\\Lib\\json\\__init__.py\", line 346, in loads\n    return _default_decoder.decode(s)\n           ^^^^^^^^^^^^^^^^^^^^^^^^^^\n  File \"C:\\Python312\\Lib\\json\\decoder.py\", line 337, in decode\n    obj, end = self.raw_decode(s, idx=_w(s, 0).end())\n               ^^^^^^^^^^^^^^^^^^^^^^^^^^^^^^^^^^^^^^\n  File \"C:\\Python312\\Lib\\json\\decoder.py\", line 355, in raw_decode\n    raise JSONDecodeError(\"Expecting value\", s, err.value) from None\njson.decoder.JSONDecodeError: Expecting value: line 1 column 1 (char 0)"}}
{"timestamp": "2025-10-18T21:26:19.896197Z", "level": "ERROR", "logger": "src.agent.rag_data_agent_v4", "message": "❌ Erro na busca RAG: {'message': 'Could not find the function public.match_embeddings_v2(match_count, match_threshold, query_embedding) in the schema cache', 'code': 'PGRST202', 'hint': 'Perhaps you meant to call the function public.match_embeddings', 'details': 'Searched for the function public.match_embeddings_v2 with parameters match_count, match_threshold, query_embedding or with a single unnamed json/jsonb parameter, but no matches were found in the schema cache.'}", "process_id": 7968, "thread_name": "MainThread", "filename": "rag_data_agent_v4.py", "line_number": 468, "function": "_search_rag_context"}
{"timestamp": "2025-10-18T21:26:58.885020Z", "level": "ERROR", "logger": "agent.rag_data", "message": "Erro ao classificar intenção: Expecting value: line 1 column 1 (char 0)", "process_id": 7968, "thread_name": "MainThread", "filename": "intent_classifier.py", "line_number": 349, "function": "classify", "exception": {"type": "JSONDecodeError", "message": "Expecting value: line 1 column 1 (char 0)", "traceback": "Traceback (most recent call last):\n  File \"C:\\workstashion\\eda-aiminds-i2a2-rb\\src\\analysis\\intent_classifier.py\", line 321, in classify\n    classification = json.loads(response_text)\n                     ^^^^^^^^^^^^^^^^^^^^^^^^^\n  File \"C:\\Python312\\Lib\\json\\__init__.py\", line 346, in loads\n    return _default_decoder.decode(s)\n           ^^^^^^^^^^^^^^^^^^^^^^^^^^\n  File \"C:\\Python312\\Lib\\json\\decoder.py\", line 337, in decode\n    obj, end = self.raw_decode(s, idx=_w(s, 0).end())\n               ^^^^^^^^^^^^^^^^^^^^^^^^^^^^^^^^^^^^^^\n  File \"C:\\Python312\\Lib\\json\\decoder.py\", line 355, in raw_decode\n    raise JSONDecodeError(\"Expecting value\", s, err.value) from None\njson.decoder.JSONDecodeError: Expecting value: line 1 column 1 (char 0)"}}
{"timestamp": "2025-10-18T21:27:00.749840Z", "level": "ERROR", "logger": "src.agent.rag_data_agent_v4", "message": "❌ Erro na busca RAG: {'message': 'Could not find the function public.match_embeddings_v2(match_count, match_threshold, query_embedding) in the schema cache', 'code': 'PGRST202', 'hint': 'Perhaps you meant to call the function public.match_embeddings', 'details': 'Searched for the function public.match_embeddings_v2 with parameters match_count, match_threshold, query_embedding or with a single unnamed json/jsonb parameter, but no matches were found in the schema cache.'}", "process_id": 7968, "thread_name": "MainThread", "filename": "rag_data_agent_v4.py", "line_number": 468, "function": "_search_rag_context"}
{"timestamp": "2025-10-18T21:27:39.764553Z", "level": "ERROR", "logger": "agent.rag_data", "message": "Erro ao classificar intenção: Expecting value: line 1 column 1 (char 0)", "process_id": 7968, "thread_name": "MainThread", "filename": "intent_classifier.py", "line_number": 349, "function": "classify", "exception": {"type": "JSONDecodeError", "message": "Expecting value: line 1 column 1 (char 0)", "traceback": "Traceback (most recent call last):\n  File \"C:\\workstashion\\eda-aiminds-i2a2-rb\\src\\analysis\\intent_classifier.py\", line 321, in classify\n    classification = json.loads(response_text)\n                     ^^^^^^^^^^^^^^^^^^^^^^^^^\n  File \"C:\\Python312\\Lib\\json\\__init__.py\", line 346, in loads\n    return _default_decoder.decode(s)\n           ^^^^^^^^^^^^^^^^^^^^^^^^^^\n  File \"C:\\Python312\\Lib\\json\\decoder.py\", line 337, in decode\n    obj, end = self.raw_decode(s, idx=_w(s, 0).end())\n               ^^^^^^^^^^^^^^^^^^^^^^^^^^^^^^^^^^^^^^\n  File \"C:\\Python312\\Lib\\json\\decoder.py\", line 355, in raw_decode\n    raise JSONDecodeError(\"Expecting value\", s, err.value) from None\njson.decoder.JSONDecodeError: Expecting value: line 1 column 1 (char 0)"}}
{"timestamp": "2025-10-18T21:27:42.075852Z", "level": "ERROR", "logger": "src.agent.rag_data_agent_v4", "message": "❌ Erro na busca RAG: {'message': 'Could not find the function public.match_embeddings_v2(match_count, match_threshold, query_embedding) in the schema cache', 'code': 'PGRST202', 'hint': 'Perhaps you meant to call the function public.match_embeddings', 'details': 'Searched for the function public.match_embeddings_v2 with parameters match_count, match_threshold, query_embedding or with a single unnamed json/jsonb parameter, but no matches were found in the schema cache.'}", "process_id": 7968, "thread_name": "MainThread", "filename": "rag_data_agent_v4.py", "line_number": 468, "function": "_search_rag_context"}
{"timestamp": "2025-10-18T21:46:33.020938Z", "level": "ERROR", "logger": "src.data.data_processor", "message": "⚠️ VIOLAÇÃO DE CONFORMIDADE DETECTADA!\nAgente 'orchestrator_agent' tentou acessar CSV diretamente.\nApenas agentes autorizados podem ler CSV: ['ingestion_agent', 'data_loading_system', 'test_system']\nAgentes de resposta devem usar APENAS a tabela embeddings.", "process_id": 15620, "thread_name": "MainThread", "filename": "data_processor.py", "line_number": 112, "function": "_validate_csv_access_authorization"}
{"timestamp": "2025-10-18T22:39:54.856997Z", "level": "ERROR", "logger": "agent.rag_data", "message": "Erro no fallback global CSV: No module named 'analysis'", "process_id": 16204, "thread_name": "MainThread", "filename": "rag_data_agent.py", "line_number": 1219, "function": "process"}
{"timestamp": "2025-10-18T23:33:56.653716Z", "level": "ERROR", "logger": "agent.rag_data", "message": "❌ Erro ao processar query: 'RAGOptimizedConfig' object has no attribute 'threshold'", "process_id": 14924, "thread_name": "MainThread", "filename": "rag_data_agent.py", "line_number": 1407, "function": "process", "exception": {"type": "AttributeError", "message": "'RAGOptimizedConfig' object has no attribute 'threshold'", "traceback": "Traceback (most recent call last):\n  File \"C:\\workstashion\\eda-aiminds-i2a2-rb\\src\\agent\\rag_data_agent.py\", line 1133, in process\n    rag_threshold = rag_config.threshold if rag_config else 0.3\n                    ^^^^^^^^^^^^^^^^^^^^\nAttributeError: 'RAGOptimizedConfig' object has no attribute 'threshold'"}}
{"timestamp": "2025-10-18T23:43:43.869404Z", "level": "ERROR", "logger": "src.data.data_processor", "message": "⚠️ VIOLAÇÃO DE CONFORMIDADE DETECTADA!\nAgente 'orchestrator_agent' tentou acessar CSV diretamente.\nApenas agentes autorizados podem ler CSV: ['ingestion_agent', 'data_loading_system', 'test_system']\nAgentes de resposta devem usar APENAS a tabela embeddings.", "process_id": 8888, "thread_name": "MainThread", "filename": "data_processor.py", "line_number": 112, "function": "_validate_csv_access_authorization"}
{"timestamp": "2025-10-19T18:26:27.944595Z", "level": "ERROR", "logger": "src.data.data_processor", "message": "⚠️ VIOLAÇÃO DE CONFORMIDADE DETECTADA!\nAgente 'orchestrator_agent' tentou acessar CSV diretamente.\nApenas agentes autorizados podem ler CSV: ['ingestion_agent', 'data_loading_system', 'test_system']\nAgentes de resposta devem usar APENAS a tabela embeddings.", "process_id": 15448, "thread_name": "MainThread", "filename": "data_processor.py", "line_number": 112, "function": "_validate_csv_access_authorization"}
